Workbook

Sheet Panel
B1: PANEL DE CONTROL | Q1: =TEXT(EDATE(TODAY(),-14),"YYYY-MM") | R1: Lista de meses del desplegable de periodo. No la borres.
B2: Elige un escenario en el desplegable y TODO el panel cambia: los importes, los semáforos, los gráficos y la proyección de la hoja Tesorería. | Q2: =TEXT(EDATE(TODAY(),-13),"YYYY-MM")
Q3: =TEXT(EDATE(TODAY(),-12),"YYYY-MM")
B4: ESCENARIO: | C4: Actual (hoy) | G4: PERIODO: | H4: 2026-08 | I4: =IF(ISNUMBER($H$4),TEXT($H$4,"YYYY-MM"),TRIM($H$4&"")) | J4: ← periodo normalizado (técnico, no borrar) | Q4: =TEXT(EDATE(TODAY(),-11),"YYYY-MM")
D5: =MATCH($C$4,Escenarios!$D$4:$H$4,0) | E5: ← columna del escenario (técnico, no borrar) | H5: =IFERROR(DATEVALUE($I$4&"-01"),TODAY()) | I5: ← primer día del periodo (técnico) | Q5: =TEXT(EDATE(TODAY(),-10),"YYYY-MM")
G6: El periodo filtra los tres estados financieros: Resultados, Balance y FlujoCaja. | Q6: =TEXT(EDATE(TODAY(),-9),"YYYY-MM")
B7: 1. ¿DÓNDE ME CONVIENE VIVIR? | K7: Datos para los gráficos | Q7: =TEXT(EDATE(TODAY(),-8),"YYYY-MM")
B8: INGRESO MENSUAL | D8: TE QUEDA PARA TI | F8: APORTAS A LA CASA | H8: AHORRAS AL MES | K8: Concepto | L8: Importe (€) | Q8: =TEXT(EDATE(TODAY(),-7),"YYYY-MM")
B9: {=INDEX(Escenarios!$D$6:$H$6,$D$5)} | D9: {=INDEX(Escenarios!$D$30:$H$30,$D$5)} | F9: {=INDEX(Escenarios!$D$29:$H$29,$D$5)} | H9: {=INDEX(Escenarios!$D$31:$H$31,$D$5)} | K9: Inversión | L9: {=INDEX(Escenarios!$D$13:$H$13,$D$5)} | Q9: =TEXT(EDATE(TODAY(),-6),"YYYY-MM")
B10: Del escenario elegido | D10: Estilo de vida − hipoteca | F10: Margen + aporte hipoteca | H10: Inversión + fondo emergencia | K10: Fondo de emergencia | L10: {=INDEX(Escenarios!$D$14:$H$14,$D$5)} | Q10: =TEXT(EDATE(TODAY(),-5),"YYYY-MM")
K11: Aporte a la hipoteca | L11: {=INDEX(Escenarios!$D$28:$H$28,$D$5)} | Q11: =TEXT(EDATE(TODAY(),-4),"YYYY-MM")
B12: Comparativa de los 5 escenarios | C12: Ingreso | D12: Gastos personales | E12: Aportas a la casa | F12: Te queda para ti | G12: Ahorro e inversión | H12: Capacidad total | K12: Tus gastos personales | L12: {=INDEX(Escenarios!$D$26:$H$26,$D$5)} | Q12: =TEXT(EDATE(TODAY(),-3),"YYYY-MM")
B13: =Escenarios!$D$4 | C13: =Escenarios!$D$6 | D13: =Escenarios!$D$26 | E13: =Escenarios!$D$29 | F13: =Escenarios!$D$30 | G13: =Escenarios!$D$31 | H13: =Escenarios!$D$54 | K13: Margen aportado a la casa | L13: {=INDEX(Escenarios!$D$27:$H$27,$D$5)} | Q13: =TEXT(EDATE(TODAY(),-2),"YYYY-MM")
B14: =Escenarios!$E$4 | C14: =Escenarios!$E$6 | D14: =Escenarios!$E$26 | E14: =Escenarios!$E$29 | F14: =Escenarios!$E$30 | G14: =Escenarios!$E$31 | H14: =Escenarios!$E$54 | K14: Te queda para ti | L14: {=INDEX(Escenarios!$D$30:$H$30,$D$5)} | Q14: =TEXT(EDATE(TODAY(),-1),"YYYY-MM")
B15: =Escenarios!$F$4 | C15: =Escenarios!$F$6 | D15: =Escenarios!$F$26 | E15: =Escenarios!$F$29 | F15: =Escenarios!$F$30 | G15: =Escenarios!$F$31 | H15: =Escenarios!$F$54 | K15: TOTAL | L15: =SUM($L$9:$L$14) | Q15: =TEXT(EDATE(TODAY(),0),"YYYY-MM")
B16: =Escenarios!$G$4 | C16: =Escenarios!$G$6 | D16: =Escenarios!$G$26 | E16: =Escenarios!$G$29 | F16: =Escenarios!$G$30 | G16: =Escenarios!$G$31 | H16: =Escenarios!$G$54 | K16: Control: debe igualar el ingreso | L16: {=$L$15-INDEX(Escenarios!$D$6:$H$6,$D$5)} | Q16: =TEXT(EDATE(TODAY(),1),"YYYY-MM")
B17: =Escenarios!$H$4 | C17: =Escenarios!$H$6 | D17: =Escenarios!$H$26 | E17: =Escenarios!$H$29 | F17: =Escenarios!$H$30 | G17: =Escenarios!$H$31 | H17: =Escenarios!$H$54 | Q17: =TEXT(EDATE(TODAY(),2),"YYYY-MM")
B18: 🏆 MEJOR EN CADA COLUMNA | C18: {=IFERROR(INDEX($B$13:$B$17,MATCH(MAX(C13:C17),C13:C17,0)),"")} | D18: {=IFERROR(INDEX($B$13:$B$17,MATCH(MIN(D13:D17),D13:D17,0)),"")} | E18: =IFERROR(INDEX($B$13:$B$17,MATCH(MAX(E13:E17),E13:E17,0)),"") | F18: =IFERROR(INDEX($B$13:$B$17,MATCH(MAX(F13:F17),F13:F17,0)),"") | G18: =IFERROR(INDEX($B$13:$B$17,MATCH(MAX(G13:G17),G13:G17,0)),"") | H18: =IFERROR(INDEX($B$13:$B$17,MATCH(MAX(H13:H17),H13:H17,0)),"") | K18: Escenario | L18: Te queda | M18: Ahorro | N18: Superávit hogar | Q18: =TEXT(EDATE(TODAY(),3),"YYYY-MM")
B19: En "Gastos personales" gana el más bajo; en el resto, el más alto. Cuidado: el escenario que más aporta a la casa puede ser el que menos te deja a ti. | K19: =Escenarios!$D$4 | L19: =Escenarios!$D$30 | M19: =Escenarios!$D$31 | N19: =Escenarios!$D$49 | Q19: =TEXT(EDATE(TODAY(),4),"YYYY-MM")
K20: =Escenarios!$E$4 | L20: =Escenarios!$E$30 | M20: =Escenarios!$E$31 | N20: =Escenarios!$E$49 | Q20: =TEXT(EDATE(TODAY(),5),"YYYY-MM")
B21: 2. ¿ME ALCANZA ESTE MES? | K21: =Escenarios!$F$4 | L21: =Escenarios!$F$30 | M21: =Escenarios!$F$31 | N21: =Escenarios!$F$49 | Q21: =TEXT(EDATE(TODAY(),6),"YYYY-MM")
B22: Disponible bancario hoy | C22: =Disponibilidad!$G$33 | K22: =Escenarios!$G$4 | L22: =Escenarios!$G$30 | M22: =Escenarios!$G$31 | N22: =Escenarios!$G$49 | Q22: =TEXT(EDATE(TODAY(),7),"YYYY-MM")
B23: Saldo pendiente de facturas | C23: =Facturas!$AG$20 | K23: =Escenarios!$H$4 | L23: =Escenarios!$H$30 | M23: =Escenarios!$H$31 | N23: =Escenarios!$H$49 | Q23: =TEXT(EDATE(TODAY(),8),"YYYY-MM")
B24: — de ello, vencido | C24: =Facturas!$AG$24 | Q24: =TEXT(EDATE(TODAY(),9),"YYYY-MM")
B25: Vencen en 7 días o menos | C25: =Facturas!$AG$25
B26: Te quedaría después de pagarlo todo | C26: =Disponibilidad!$G$40 | K26: Objetivo | L26: Importe (€)
B27: Cobertura (veces) | C27: =IFERROR(Disponibilidad!$G$41,"") | K27: Patrimonio hoy | L27: {=INDEX(Escenarios!$D$64:$H$64,$D$5)}
B28: Días de autonomía | C28: =IFERROR(Disponibilidad!$G$43,"") | K28: Objetivo 120 meses | L28: {=INDEX(Escenarios!$D$61:$H$61,$D$5)}
B29: Saldo mínimo proyectado en 30 días | C29: =Tesoreria!$P$67 | K29: Objetivo regla 4% | L29: {=INDEX(Escenarios!$D$63:$H$63,$D$5)}
B30: DIAGNÓSTICO | C30: =Disponibilidad!$G$44
B32: 3. ¿CUÁNDO LLEGO A LA INDEPENDENCIA FINANCIERA?
B33: Gasto mensual que tendrías que cubrir sin trabajar | C33: {=INDEX(Escenarios!$D$59:$H$59,$D$5)}
B34: Objetivo con TU regla (gasto × 120 meses) | C34: {=INDEX(Escenarios!$D$61:$H$61,$D$5)}
B35: Objetivo con la regla del 4% (gasto × 300 meses) | C35: {=INDEX(Escenarios!$D$63:$H$63,$D$5)}
B36: Patrimonio invertido hoy | C36: {=INDEX(Escenarios!$D$64:$H$64,$D$5)}
B37: Aporte mensual a inversión | C37: {=INDEX(Escenarios!$D$13:$H$13,$D$5)}
B38: Progreso hacia el objetivo del 4% | C38: {=INDEX(Escenarios!$D$68:$H$68,$D$5)}
B39: Barra de progreso | C39: =IF($C$38="","",REPT("█",MAX(0,ROUND($C$38*40,0)))&REPT("░",40-MAX(0,ROUND($C$38*40,0))))
B40: Años hasta TU objetivo | C40: {=INDEX(Escenarios!$D$66:$H$66,$D$5)}
B41: Años hasta el objetivo del 4% | C41: {=INDEX(Escenarios!$D$67:$H$67,$D$5)}
...

Sheet Citas
B1: CALENDARIO DE CITAS
B2: Arriba tienes el mes actual (o el que elijas) en grande, y más abajo los doce meses del año de un vistazo. Escribe tus citas en el REGISTRO del final y todo se pinta solo, con el color de la prioridad más alta de cada día. Las filas de ejemplo están marcadas "(ejemplo)": bórralas cuando metas las tuyas.
B4: AÑO: | D4: 2026 | G4: MES: | I4: Actual (hoy) | M4: =IFERROR(IF(OR($I$4="Actual (hoy)",$I$4=""),MONTH(TODAY()),MATCH($I$4,{"Enero";"Febrero";"Marzo";"Abril";"Mayo";"Junio";"Julio";"Agosto";"Septiembre";"Octubre";"Noviembre";"Diciembre"},0)),MONTH(TODAY())) | O4: =" Mostrando: "&INDEX({"Enero";"Febrero";"Marzo";"Abril";"Mayo";"Junio";"Julio";"Agosto";"Septiembre";"Octubre";"Noviembre";"Diciembre"},$M$4)&" de "&$D$4&" ▸ pinta el calendario grande de arriba"
B5: LEYENDA: | J5: 1 · Urgente | M5: 2 · Alta | P5: 3 · Media | S5: 4 · Baja | V5: Sin prioridad
B7: CITAS DEL AÑO | H7: PENDIENTES | N7: URGENTES PENDIENTES | T7: PRÓXIMA CITA
B8: =COUNTIFS($B$62:$B$211,">="&DATE($D$4,1,1),$B$62:$B$211,"<="&DATE($D$4,12,31),$V$62:$V$211,"<>4 · Cancelada") | H8: =COUNTIFS($B$62:$B$211,">="&TODAY(),$V$62:$V$211,"<>4 · Cancelada",$V$62:$V$211,"<>3 · Hecha") | N8: =COUNTIFS($B$62:$B$211,">="&TODAY(),$S$62:$S$211,"1 · Urgente",$V$62:$V$211,"<>4 · Cancelada",$V$62:$V$211,"<>3 · Hecha") | T8: =IF(COUNT($Z$62:$Z$211)=0,"—",MIN($Z$62:$Z$211))
B9: Sin contar las canceladas | H9: Aún por celebrar | N9: Prioridad 1 sin celebrar | T9: La primera que llega
B10: =IFERROR(IF(COUNT($Z$62:$Z$211)=0,"📭 No tienes ninguna cita futura registrada.","📌 Siguiente: "&TEXT(MIN($Z$62:$Z$211),"DD/MM/YYYY")&" · "&INDEX($G$62:$G$211,MATCH(MIN($Z$62:$Z$211),$B$62:$B$211,0))&" · "&IF(MIN($Z$62:$Z$211)=TODAY(),"es HOY","faltan "&(MIN($Z$62:$Z$211)-TODAY())&" días")),"")
B12: ="★ "&UPPER(INDEX({"Enero";"Febrero";"Marzo";"Abril";"Mayo";"Junio";"Julio";"Agosto";"Septiembre";"Octubre";"Noviembre";"Diciembre"},$M$4))&" "&$D$4 | G12: =COUNTIFS($B$62:$B$211,">="&DATE($D$4,$M$4,1),$B$62:$B$211,"<="&EOMONTH(DATE($D$4,$M$4,1),0),$V$62:$V$211,"<>4 · Cancelada")&" citas"
B13: L | C13: M | D13: X | E13: J | F13: V | G13: S | H13: D
B14: =IF(MONTH(DATE($D$4,$M$4,1)-WEEKDAY(DATE($D$4,$M$4,1),2)+1+0)<>$M$4,"",DATE($D$4,$M$4,1)-WEEKDAY(DATE($D$4,$M$4,1),2)+1+0) | C14: =IF(MONTH(DATE($D$4,$M$4,1)-WEEKDAY(DATE($D$4,$M$4,1),2)+1+1)<>$M$4,"",DATE($D$4,$M$4,1)-WEEKDAY(DATE($D$4,$M$4,1),2)+1+1) | D14: =IF(MONTH(DATE($D$4,$M$4,1)-WEEKDAY(DATE($D$4,$M$4,1),2)+1+2)<>$M$4,"",DATE($D$4,$M$4,1)-WEEKDAY(DATE($D$4,$M$4,1),2)+1+2) | E14: =IF(MONTH(DATE($D$4,$M$4,1)-WEEKDAY(DATE($D$4,$M$4,1),2)+1+3)<>$M$4,"",DATE($D$4,$M$4,1)-WEEKDAY(DATE($D$4,$M$4,1),2)+1+3) | F14: =IF(MONTH(DATE($D$4,$M$4,1)-WEEKDAY(DATE($D$4,$M$4,1),2)+1+4)<>$M$4,"",DATE($D$4,$M$4,1)-WEEKDAY(DATE($D$4,$M$4,1),2)+1+4) | G14: =IF(MONTH(DATE($D$4,$M$4,1)-WEEKDAY(DATE($D$4,$M$4,1),2)+1+5)<>$M$4,"",DATE($D$4,$M$4,1)-WEEKDAY(DATE($D$4,$M$4,1),2)+1+5) | H14: =IF(MONTH(DATE($D$4,$M$4,1)-WEEKDAY(DATE($D$4,$M$4,1),2)+1+6)<>$M$4,"",DATE($D$4,$M$4,1)-WEEKDAY(DATE($D$4,$M$4,1),2)+1+6)
B15: =IF(MONTH(DATE($D$4,$M$4,1)-WEEKDAY(DATE($D$4,$M$4,1),2)+1+7)<>$M$4,"",DATE($D$4,$M$4,1)-WEEKDAY(DATE($D$4,$M$4,1),2)+1+7) | C15: =IF(MONTH(DATE($D$4,$M$4,1)-WEEKDAY(DATE($D$4,$M$4,1),2)+1+8)<>$M$4,"",DATE($D$4,$M$4,1)-WEEKDAY(DATE($D$4,$M$4,1),2)+1+8) | D15: =IF(MONTH(DATE($D$4,$M$4,1)-WEEKDAY(DATE($D$4,$M$4,1),2)+1+9)<>$M$4,"",DATE($D$4,$M$4,1)-WEEKDAY(DATE($D$4,$M$4,1),2)+1+9) | E15: =IF(MONTH(DATE($D$4,$M$4,1)-WEEKDAY(DATE($D$4,$M$4,1),2)+1+10)<>$M$4,"",DATE($D$4,$M$4,1)-WEEKDAY(DATE($D$4,$M$4,1),2)+1+10) | F15: =IF(MONTH(DATE($D$4,$M$4,1)-WEEKDAY(DATE($D$4,$M$4,1),2)+1+11)<>$M$4,"",DATE($D$4,$M$4,1)-WEEKDAY(DATE($D$4,$M$4,1),2)+1+11) | G15: =IF(MONTH(DATE($D$4,$M$4,1)-WEEKDAY(DATE($D$4,$M$4,1),2)+1+12)<>$M$4,"",DATE($D$4,$M$4,1)-WEEKDAY(DATE($D$4,$M$4,1),2)+1+12) | H15: =IF(MONTH(DATE($D$4,$M$4,1)-WEEKDAY(DATE($D$4,$M$4,1),2)+1+13)<>$M$4,"",DATE($D$4,$M$4,1)-WEEKDAY(DATE($D$4,$M$4,1),2)+1+13)
B16: =IF(MONTH(DATE($D$4,$M$4,1)-WEEKDAY(DATE($D$4,$M$4,1),2)+1+14)<>$M$4,"",DATE($D$4,$M$4,1)-WEEKDAY(DATE($D$4,$M$4,1),2)+1+14) | C16: =IF(MONTH(DATE($D$4,$M$4,1)-WEEKDAY(DATE($D$4,$M$4,1),2)+1+15)<>$M$4,"",DATE($D$4,$M$4,1)-WEEKDAY(DATE($D$4,$M$4,1),2)+1+15) | D16: =IF(MONTH(DATE($D$4,$M$4,1)-WEEKDAY(DATE($D$4,$M$4,1),2)+1+16)<>$M$4,"",DATE($D$4,$M$4,1)-WEEKDAY(DATE($D$4,$M$4,1),2)+1+16) | E16: =IF(MONTH(DATE($D$4,$M$4,1)-WEEKDAY(DATE($D$4,$M$4,1),2)+1+17)<>$M$4,"",DATE($D$4,$M$4,1)-WEEKDAY(DATE($D$4,$M$4,1),2)+1+17) | F16: =IF(MONTH(DATE($D$4,$M$4,1)-WEEKDAY(DATE($D$4,$M$4,1),2)+1+18)<>$M$4,"",DATE($D$4,$M$4,1)-WEEKDAY(DATE($D$4,$M$4,1),2)+1+18) | G16: =IF(MONTH(DATE($D$4,$M$4,1)-WEEKDAY(DATE($D$4,$M$4,1),2)+1+19)<>$M$4,"",DATE($D$4,$M$4,1)-WEEKDAY(DATE($D$4,$M$4,1),2)+1+19) | H16: =IF(MONTH(DATE($D$4,$M$4,1)-WEEKDAY(DATE($D$4,$M$4,1),2)+1+20)<>$M$4,"",DATE($D$4,$M$4,1)-WEEKDAY(DATE($D$4,$M$4,1),2)+1+20)
B17: =IF(MONTH(DATE($D$4,$M$4,1)-WEEKDAY(DATE($D$4,$M$4,1),2)+1+21)<>$M$4,"",DATE($D$4,$M$4,1)-WEEKDAY(DATE($D$4,$M$4,1),2)+1+21) | C17: =IF(MONTH(DATE($D$4,$M$4,1)-WEEKDAY(DATE($D$4,$M$4,1),2)+1+22)<>$M$4,"",DATE($D$4,$M$4,1)-WEEKDAY(DATE($D$4,$M$4,1),2)+1+22) | D17: =IF(MONTH(DATE($D$4,$M$4,1)-WEEKDAY(DATE($D$4,$M$4,1),2)+1+23)<>$M$4,"",DATE($D$4,$M$4,1)-WEEKDAY(DATE($D$4,$M$4,1),2)+1+23) | E17: =IF(MONTH(DATE($D$4,$M$4,1)-WEEKDAY(DATE($D$4,$M$4,1),2)+1+24)<>$M$4,"",DATE($D$4,$M$4,1)-WEEKDAY(DATE($D$4,$M$4,1),2)+1+24) | F17: =IF(MONTH(DATE($D$4,$M$4,1)-WEEKDAY(DATE($D$4,$M$4,1),2)+1+25)<>$M$4,"",DATE($D$4,$M$4,1)-WEEKDAY(DATE($D$4,$M$4,1),2)+1+25) | G17: =IF(MONTH(DATE($D$4,$M$4,1)-WEEKDAY(DATE($D$4,$M$4,1),2)+1+26)<>$M$4,"",DATE($D$4,$M$4,1)-WEEKDAY(DATE($D$4,$M$4,1),2)+1+26) | H17: =IF(MONTH(DATE($D$4,$M$4,1)-WEEKDAY(DATE($D$4,$M$4,1),2)+1+27)<>$M$4,"",DATE($D$4,$M$4,1)-WEEKDAY(DATE($D$4,$M$4,1),2)+1+27)
B18: =IF(MONTH(DATE($D$4,$M$4,1)-WEEKDAY(DATE($D$4,$M$4,1),2)+1+28)<>$M$4,"",DATE($D$4,$M$4,1)-WEEKDAY(DATE($D$4,$M$4,1),2)+1+28) | C18: =IF(MONTH(DATE($D$4,$M$4,1)-WEEKDAY(DATE($D$4,$M$4,1),2)+1+29)<>$M$4,"",DATE($D$4,$M$4,1)-WEEKDAY(DATE($D$4,$M$4,1),2)+1+29) | D18: =IF(MONTH(DATE($D$4,$M$4,1)-WEEKDAY(DATE($D$4,$M$4,1),2)+1+30)<>$M$4,"",DATE($D$4,$M$4,1)-WEEKDAY(DATE($D$4,$M$4,1),2)+1+30) | E18: =IF(MONTH(DATE($D$4,$M$4,1)-WEEKDAY(DATE($D$4,$M$4,1),2)+1+31)<>$M$4,"",DATE($D$4,$M$4,1)-WEEKDAY(DATE($D$4,$M$4,1),2)+1+31) | F18: =IF(MONTH(DATE($D$4,$M$4,1)-WEEKDAY(DATE($D$4,$M$4,1),2)+1+32)<>$M$4,"",DATE($D$4,$M$4,1)-WEEKDAY(DATE($D$4,$M$4,1),2)+1+32) | G18: =IF(MONTH(DATE($D$4,$M$4,1)-WEEKDAY(DATE($D$4,$M$4,1),2)+1+33)<>$M$4,"",DATE($D$4,$M$4,1)-WEEKDAY(DATE($D$4,$M$4,1),2)+1+33) | H18: =IF(MONTH(DATE($D$4,$M$4,1)-WEEKDAY(DATE($D$4,$M$4,1),2)+1+34)<>$M$4,"",DATE($D$4,$M$4,1)-WEEKDAY(DATE($D$4,$M$4,1),2)+1+34)
B19: =IF(MONTH(DATE($D$4,$M$4,1)-WEEKDAY(DATE($D$4,$M$4,1),2)+1+35)<>$M$4,"",DATE($D$4,$M$4,1)-WEEKDAY(DATE($D$4,$M$4,1),2)+1+35) | C19: =IF(MONTH(DATE($D$4,$M$4,1)-WEEKDAY(DATE($D$4,$M$4,1),2)+1+36)<>$M$4,"",DATE($D$4,$M$4,1)-WEEKDAY(DATE($D$4,$M$4,1),2)+1+36) | D19: =IF(MONTH(DATE($D$4,$M$4,1)-WEEKDAY(DATE($D$4,$M$4,1),2)+1+37)<>$M$4,"",DATE($D$4,$M$4,1)-WEEKDAY(DATE($D$4,$M$4,1),2)+1+37) | E19: =IF(MONTH(DATE($D$4,$M$4,1)-WEEKDAY(DATE($D$4,$M$4,1),2)+1+38)<>$M$4,"",DATE($D$4,$M$4,1)-WEEKDAY(DATE($D$4,$M$4,1),2)+1+38) | F19: =IF(MONTH(DATE($D$4,$M$4,1)-WEEKDAY(DATE($D$4,$M$4,1),2)+1+39)<>$M$4,"",DATE($D$4,$M$4,1)-WEEKDAY(DATE($D$4,$M$4,1),2)+1+39) | G19: =IF(MONTH(DATE($D$4,$M$4,1)-WEEKDAY(DATE($D$4,$M$4,1),2)+1+40)<>$M$4,"",DATE($D$4,$M$4,1)-WEEKDAY(DATE($D$4,$M$4,1),2)+1+40) | H19: =IF(MONTH(DATE($D$4,$M$4,1)-WEEKDAY(DATE($D$4,$M$4,1),2)+1+41)<>$M$4,"",DATE($D$4,$M$4,1)-WEEKDAY(DATE($D$4,$M$4,1),2)+1+41)
B21: LOS 12 MESES DEL AÑO — de un vistazo
B23: ="ENERO "&$D$4 | G23: =IF(COUNTIFS($B$62:$B$211,">="&DATE($D$4,1,1),$B$62:$B$211,"<="&EOMONTH(DATE($D$4,1,1),0),$V$62:$V$211,"<>4 · Cancelada")=1,"1 cita",COUNTIFS($B$62:$B$211,">="&DATE($D$4,1,1),$B$62:$B$211,"<="&EOMONTH(DATE($D$4,1,1),0),$V$62:$V$211,"<>4 · Cancelada")&" citas") | J23: ="FEBRERO "&$D$4 | O23: =IF(COUNTIFS($B$62:$B$211,">="&DATE($D$4,2,1),$B$62:$B$211,"<="&EOMONTH(DATE($D$4,2,1),0),$V$62:$V$211,"<>4 · Cancelada")=1,"1 cita",COUNTIFS($B$62:$B$211,">="&DATE($D$4,2,1),$B$62:$B$211,"<="&EOMONTH(DATE($D$4,2,1),0),$V$62:$V$211,"<>4 · Cancelada")&" citas") | R23: ="MARZO "&$D$4 | W23: =IF(COUNTIFS($B$62:$B$211,">="&DATE($D$4,3,1),$B$62:$B$211,"<="&EOMONTH(DATE($D$4,3,1),0),$V$62:$V$211,"<>4 · Cancelada")=1,"1 cita",COUNTIFS($B$62:$B$211,">="&DATE($D$4,3,1),$B$62:$B$211,"<="&EOMONTH(DATE($D$4,3,1),0),$V$62:$V$211,"<>4 · Cancelada")&" citas")
B24: L | C24: M | D24: X | E24: J | F24: V | G24: S | H24: D | J24: L | K24: M | L24: X | M24: J | N24: V | O24: S | P24: D | R24: L | S24: M | T24: X | U24: J | V24: V | W24: S | X24: D
B25: =IF(MONTH(DATE($D$4,1,1)-WEEKDAY(DATE($D$4,1,1),2)+1+0)<>1,"",DATE($D$4,1,1)-WEEKDAY(DATE($D$4,1,1),2)+1+0) | C25: =IF(MONTH(DATE($D$4,1,1)-WEEKDAY(DATE($D$4,1,1),2)+1+1)<>1,"",DATE($D$4,1,1)-WEEKDAY(DATE($D$4,1,1),2)+1+1) | D25: =IF(MONTH(DATE($D$4,1,1)-WEEKDAY(DATE($D$4,1,1),2)+1+2)<>1,"",DATE($D$4,1,1)-WEEKDAY(DATE($D$4,1,1),2)+1+2) | E25: =IF(MONTH(DATE($D$4,1,1)-WEEKDAY(DATE($D$4,1,1),2)+1+3)<>1,"",DATE($D$4,1,1)-WEEKDAY(DATE($D$4,1,1),2)+1+3) | F25: =IF(MONTH(DATE($D$4,1,1)-WEEKDAY(DATE($D$4,1,1),2)+1+4)<>1,"",DATE($D$4,1,1)-WEEKDAY(DATE($D$4,1,1),2)+1+4) | G25: =IF(MONTH(DATE($D$4,1,1)-WEEKDAY(DATE($D$4,1,1),2)+1+5)<>1,"",DATE($D$4,1,1)-WEEKDAY(DATE($D$4,1,1),2)+1+5) | H25: =IF(MONTH(DATE($D$4,1,1)-WEEKDAY(DATE($D$4,1,1),2)+1+6)<>1,"",DATE($D$4,1,1)-WEEKDAY(DATE($D$4,1,1),2)+1+6) | J25: =IF(MONTH(DATE($D$4,2,1)-WEEKDAY(DATE($D$4,2,1),2)+1+0)<>2,"",DATE($D$4,2,1)-WEEKDAY(DATE($D$4,2,1),2)+1+0) | K25: =IF(MONTH(DATE($D$4,2,1)-WEEKDAY(DATE($D$4,2,1),2)+1+1)<>2,"",DATE($D$4,2,1)-WEEKDAY(DATE($D$4,2,1),2)+1+1) | L25: =IF(MONTH(DATE($D$4,2,1)-WEEKDAY(DATE($D$4,2,1),2)+1+2)<>2,"",DATE($D$4,2,1)-WEEKDAY(DATE($D$4,2,1),2)+1+2) | M25: =IF(MONTH(DATE($D$4,2,1)-WEEKDAY(DATE($D$4,2,1),2)+1+3)<>2,"",DATE($D$4,2,1)-WEEKDAY(DATE($D$4,2,1),2)+1+3) | N25: =IF(MONTH(DATE($D$4,2,1)-WEEKDAY(DATE($D$4,2,1),2)+1+4)<>2,"",DATE($D$4,2,1)-WEEKDAY(DATE($D$4,2,1),2)+1+4) | O25: =IF(MONTH(DATE($D$4,2,1)-WEEKDAY(DATE($D$4,2,1),2)+1+5)<>2,"",DATE($D$4,2,1)-WEEKDAY(DATE($D$4,2,1),2)+1+5) | P25: =IF(MONTH(DATE($D$4,2,1)-WEEKDAY(DATE($D$4,2,1),2)+1+6)<>2,"",DATE($D$4,2,1)-WEEKDAY(DATE($D$4,2,1),2)+1+6) | R25: =IF(MONTH(DATE($D$4,3,1)-WEEKDAY(DATE($D$4,3,1),2)+1+0)<>3,"",DATE($D$4,3,1)-WEEKDAY(DATE($D$4,3,1),2)+1+0) | S25: =IF(MONTH(DATE($D$4,3,1)-WEEKDAY(DATE($D$4,3,1),2)+1+1)<>3,"",DATE($D$4,3,1)-WEEKDAY(DATE($D$4,3,1),2)+1+1) | T25: =IF(MONTH(DATE($D$4,3,1)-WEEKDAY(DATE($D$4,3,1),2)+1+2)<>3,"",DATE($D$4,3,1)-WEEKDAY(DATE($D$4,3,1),2)+1+2) | U25: =IF(MONTH(DATE($D$4,3,1)-WEEKDAY(DATE($D$4,3,1),2)+1+3)<>3,"",DATE($D$4,3,1)-WEEKDAY(DATE($D$4,3,1),2)+1+3) | V25: =IF(MONTH(DATE($D$4,3,1)-WEEKDAY(DATE($D$4,3,1),2)+1+4)<>3,"",DATE($D$4,3,1)-WEEKDAY(DATE($D$4,3,1),2)+1+4) | W25: =IF(MONTH(DATE($D$4,3,1)-WEEKDAY(DATE($D$4,3,1),2)+1+5)<>3,"",DATE($D$4,3,1)-WEEKDAY(DATE($D$4,3,1),2)+1+5) | X25: =IF(MONTH(DATE($D$4,3,1)-WEEKDAY(DATE($D$4,3,1),2)+1+6)<>3,"",DATE($D$4,3,1)-WEEKDAY(DATE($D$4,3,1),2)+1+6)
B26: =IF(MONTH(DATE($D$4,1,1)-WEEKDAY(DATE($D$4,1,1),2)+1+7)<>1,"",DATE($D$4,1,1)-WEEKDAY(DATE($D$4,1,1),2)+1+7) | C26: =IF(MONTH(DATE($D$4,1,1)-WEEKDAY(DATE($D$4,1,1),2)+1+8)<>1,"",DATE($D$4,1,1)-WEEKDAY(DATE($D$4,1,1),2)+1+8) | D26: =IF(MONTH(DATE($D$4,1,1)-WEEKDAY(DATE($D$4,1,1),2)+1+9)<>1,"",DATE($D$4,1,1)-WEEKDAY(DATE($D$4,1,1),2)+1+9) | E26: =IF(MONTH(DATE($D$4,1,1)-WEEKDAY(DATE($D$4,1,1),2)+1+10)<>1,"",DATE($D$4,1,1)-WEEKDAY(DATE($D$4,1,1),2)+1+10) | F26: =IF(MONTH(DATE($D$4,1,1)-WEEKDAY(DATE($D$4,1,1),2)+1+11)<>1,"",DATE($D$4,1,1)-WEEKDAY(DATE($D$4,1,1),2)+1+11) | G26: =IF(MONTH(DATE($D$4,1,1)-WEEKDAY(DATE($D$4,1,1),2)+1+12)<>1,"",DATE($D$4,1,1)-WEEKDAY(DATE($D$4,1,1),2)+1+12) | H26: =IF(MONTH(DATE($D$4,1,1)-WEEKDAY(DATE($D$4,1,1),2)+1+13)<>1,"",DATE($D$4,1,1)-WEEKDAY(DATE($D$4,1,1),2)+1+13) | J26: =IF(MONTH(DATE($D$4,2,1)-WEEKDAY(DATE($D$4,2,1),2)+1+7)<>2,"",DATE($D$4,2,1)-WEEKDAY(DATE($D$4,2,1),2)+1+7) | K26: =IF(MONTH(DATE($D$4,2,1)-WEEKDAY(DATE($D$4,2,1),2)+1+8)<>2,"",DATE($D$4,2,1)-WEEKDAY(DATE($D$4,2,1),2)+1+8) | L26: =IF(MONTH(DATE($D$4,2,1)-WEEKDAY(DATE($D$4,2,1),2)+1+9)<>2,"",DATE($D$4,2,1)-WEEKDAY(DATE($D$4,2,1),2)+1+9) | M26: =IF(MONTH(DATE($D$4,2,1)-WEEKDAY(DATE($D$4,2,1),2)+1+10)<>2,"",DATE($D$4,2,1)-WEEKDAY(DATE($D$4,2,1),2)+1+10) | N26: =IF(MONTH(DATE($D$4,2,1)-WEEKDAY(DATE($D$4,2,1),2)+1+11)<>2,"",DATE($D$4,2,1)-WEEKDAY(DATE($D$4,2,1),2)+1+11) | O26: =IF(MONTH(DATE($D$4,2,1)-WEEKDAY(DATE($D$4,2,1),2)+1+12)<>2,"",DATE($D$4,2,1)-WEEKDAY(DATE($D$4,2,1),2)+1+12) | P26: =IF(MONTH(DATE($D$4,2,1)-WEEKDAY(DATE($D$4,2,1),2)+1+13)<>2,"",DATE($D$4,2,1)-WEEKDAY(DATE($D$4,2,1),2)+1+13) | R26: =IF(MONTH(DATE($D$4,3,1)-WEEKDAY(DATE($D$4,3,1),2)+1+7)<>3,"",DATE($D$4,3,1)-WEEKDAY(DATE($D$4,3,1),2)+1+7) | S26: =IF(MONTH(DATE($D$4,3,1)-WEEKDAY(DATE($D$4,3,1),2)+1+8)<>3,"",DATE($D$4,3,1)-WEEKDAY(DATE($D$4,3,1),2)+1+8) | T26: =IF(MONTH(DATE($D$4,3,1)-WEEKDAY(DATE($D$4,3,1),2)+1+9)<>3,"",DATE($D$4,3,1)-WEEKDAY(DATE($D$4,3,1),2)+1+9) | U26: =IF(MONTH(DATE($D$4,3,1)-WEEKDAY(DATE($D$4,3,1),2)+1+10)<>3,"",DATE($D$4,3,1)-WEEKDAY(DATE($D$4,3,1),2)+1+10) | V26: =IF(MONTH(DATE($D$4,3,1)-WEEKDAY(DATE($D$4,3,1),2)+1+11)<>3,"",DATE($D$4,3,1)-WEEKDAY(DATE($D$4,3,1),2)+1+11) | W26: =IF(MONTH(DATE($D$4,3,1)-WEEKDAY(DATE($D$4,3,1),2)+1+12)<>3,"",DATE($D$4,3,1)-WEEKDAY(DATE($D$4,3,1),2)+1+12) | X26: =IF(MONTH(DATE($D$4,3,1)-WEEKDAY(DATE($D$4,3,1),2)+1+13)<>3,"",DATE($D$4,3,1)-WEEKDAY(DATE($D$4,3,1),2)+1+13)
B27: =IF(MONTH(DATE($D$4,1,1)-WEEKDAY(DATE($D$4,1,1),2)+1+14)<>1,"",DATE($D$4,1,1)-WEEKDAY(DATE($D$4,1,1),2)+1+14) | C27: =IF(MONTH(DATE($D$4,1,1)-WEEKDAY(DATE($D$4,1,1),2)+1+15)<>1,"",DATE($D$4,1,1)-WEEKDAY(DATE($D$4,1,1),2)+1+15) | D27: =IF(MONTH(DATE($D$4,1,1)-WEEKDAY(DATE($D$4,1,1),2)+1+16)<>1,"",DATE($D$4,1,1)-WEEKDAY(DATE($D$4,1,1),2)+1+16) | E27: =IF(MONTH(DATE($D$4,1,1)-WEEKDAY(DATE($D$4,1,1),2)+1+17)<>1,"",DATE($D$4,1,1)-WEEKDAY(DATE($D$4,1,1),2)+1+17) | F27: =IF(MONTH(DATE($D$4,1,1)-WEEKDAY(DATE($D$4,1,1),2)+1+18)<>1,"",DATE($D$4,1,1)-WEEKDAY(DATE($D$4,1,1),2)+1+18) | G27: =IF(MONTH(DATE($D$4,1,1)-WEEKDAY(DATE($D$4,1,1),2)+1+19)<>1,"",DATE($D$4,1,1)-WEEKDAY(DATE($D$4,1,1),2)+1+19) | H27: =IF(MONTH(DATE($D$4,1,1)-WEEKDAY(DATE($D$4,1,1),2)+1+20)<>1,"",DATE($D$4,1,1)-WEEKDAY(DATE($D$4,1,1),2)+1+20) | J27: =IF(MONTH(DATE($D$4,2,1)-WEEKDAY(DATE($D$4,2,1),2)+1+14)<>2,"",DATE($D$4,2,1)-WEEKDAY(DATE($D$4,2,1),2)+1+14) | K27: =IF(MONTH(DATE($D$4,2,1)-WEEKDAY(DATE($D$4,2,1),2)+1+15)<>2,"",DATE($D$4,2,1)-WEEKDAY(DATE($D$4,2,1),2)+1+15) | L27: =IF(MONTH(DATE($D$4,2,1)-WEEKDAY(DATE($D$4,2,1),2)+1+16)<>2,"",DATE($D$4,2,1)-WEEKDAY(DATE($D$4,2,1),2)+1+16) | M27: =IF(MONTH(DATE($D$4,2,1)-WEEKDAY(DATE($D$4,2,1),2)+1+17)<>2,"",DATE($D$4,2,1)-WEEKDAY(DATE($D$4,2,1),2)+1+17) | N27: =IF(MONTH(DATE($D$4,2,1)-WEEKDAY(DATE($D$4,2,1),2)+1+18)<>2,"",DATE($D$4,2,1)-WEEKDAY(DATE($D$4,2,1),2)+1+18) | O27: =IF(MONTH(DATE($D$4,2,1)-WEEKDAY(DATE($D$4,2,1),2)+1+19)<>2,"",DATE($D$4,2,1)-WEEKDAY(DATE($D$4,2,1),2)+1+19) | P27: =IF(MONTH(DATE($D$4,2,1)-WEEKDAY(DATE($D$4,2,1),2)+1+20)<>2,"",DATE($D$4,2,1)-WEEKDAY(DATE($D$4,2,1),2)+1+20) | R27: =IF(MONTH(DATE($D$4,3,1)-WEEKDAY(DATE($D$4,3,1),2)+1+14)<>3,"",DATE($D$4,3,1)-WEEKDAY(DATE($D$4,3,1),2)+1+14) | S27: =IF(MONTH(DATE($D$4,3,1)-WEEKDAY(DATE($D$4,3,1),2)+1+15)<>3,"",DATE($D$4,3,1)-WEEKDAY(DATE($D$4,3,1),2)+1+15) | T27: =IF(MONTH(DATE($D$4,3,1)-WEEKDAY(DATE($D$4,3,1),2)+1+16)<>3,"",DATE($D$4,3,1)-WEEKDAY(DATE($D$4,3,1),2)+1+16) | U27: =IF(MONTH(DATE($D$4,3,1)-WEEKDAY(DATE($D$4,3,1),2)+1+17)<>3,"",DATE($D$4,3,1)-WEEKDAY(DATE($D$4,3,1),2)+1+17) | V27: =IF(MONTH(DATE($D$4,3,1)-WEEKDAY(DATE($D$4,3,1),2)+1+18)<>3,"",DATE($D$4,3,1)-WEEKDAY(DATE($D$4,3,1),2)+1+18) | W27: =IF(MONTH(DATE($D$4,3,1)-WEEKDAY(DATE($D$4,3,1),2)+1+19)<>3,"",DATE($D$4,3,1)-WEEKDAY(DATE($D$4,3,1),2)+1+19) | X27: =IF(MONTH(DATE($D$4,3,1)-WEEKDAY(DATE($D$4,3,1),2)+1+20)<>3,"",DATE($D$4,3,1)-WEEKDAY(DATE($D$4,3,1),2)+1+20)
B28: =IF(MONTH(DATE($D$4,1,1)-WEEKDAY(DATE($D$4,1,1),2)+1+21)<>1,"",DATE($D$4,1,1)-WEEKDAY(DATE($D$4,1,1),2)+1+21) | C28: =IF(MONTH(DATE($D$4,1,1)-WEEKDAY(DATE($D$4,1,1),2)+1+22)<>1,"",DATE($D$4,1,1)-WEEKDAY(DATE($D$4,1,1),2)+1+22) | D28: =IF(MONTH(DATE($D$4,1,1)-WEEKDAY(DATE($D$4,1,1),2)+1+23)<>1,"",DATE($D$4,1,1)-WEEKDAY(DATE($D$4,1,1),2)+1+23) | E28: =IF(MONTH(DATE($D$4,1,1)-WEEKDAY(DATE($D$4,1,1),2)+1+24)<>1,"",DATE($D$4,1,1)-WEEKDAY(DATE($D$4,1,1),2)+1+24) | F28: =IF(MONTH(DATE($D$4,1,1)-WEEKDAY(DATE($D$4,1,1),2)+1+25)<>1,"",DATE($D$4,1,1)-WEEKDAY(DATE($D$4,1,1),2)+1+25) | G28: =IF(MONTH(DATE($D$4,1,1)-WEEKDAY(DATE($D$4,1,1),2)+1+26)<>1,"",DATE($D$4,1,1)-WEEKDAY(DATE($D$4,1,1),2)+1+26) | H28: =IF(MONTH(DATE($D$4,1,1)-WEEKDAY(DATE($D$4,1,1),2)+1+27)<>1,"",DATE($D$4,1,1)-WEEKDAY(DATE($D$4,1,1),2)+1+27) | J28: =IF(MONTH(DATE($D$4,2,1)-WEEKDAY(DATE($D$4,2,1),2)+1+21)<>2,"",DATE($D$4,2,1)-WEEKDAY(DATE($D$4,2,1),2)+1+21) | K28: =IF(MONTH(DATE($D$4,2,1)-WEEKDAY(DATE($D$4,2,1),2)+1+22)<>2,"",DATE($D$4,2,1)-WEEKDAY(DATE($D$4,2,1),2)+1+22) | L28: =IF(MONTH(DATE($D$4,2,1)-WEEKDAY(DATE($D$4,2,1),2)+1+23)<>2,"",DATE($D$4,2,1)-WEEKDAY(DATE($D$4,2,1),2)+1+23) | M28: =IF(MONTH(DATE($D$4,2,1)-WEEKDAY(DATE($D$4,2,1),2)+1+24)<>2,"",DATE($D$4,2,1)-WEEKDAY(DATE($D$4,2,1),2)+1+24) | N28: =IF(MONTH(DATE($D$4,2,1)-WEEKDAY(DATE($D$4,2,1),2)+1+25)<>2,"",DATE($D$4,2,1)-WEEKDAY(DATE($D$4,2,1),2)+1+25) | O28: =IF(MONTH(DATE($D$4,2,1)-WEEKDAY(DATE($D$4,2,1),2)+1+26)<>2,"",DATE($D$4,2,1)-WEEKDAY(DATE($D$4,2,1),2)+1+26) | P28: =IF(MONTH(DATE($D$4,2,1)-WEEKDAY(DATE($D$4,2,1),2)+1+27)<>2,"",DATE($D$4,2,1)-WEEKDAY(DATE($D$4,2,1),2)+1+27) | R28: =IF(MONTH(DATE($D$4,3,1)-WEEKDAY(DATE($D$4,3,1),2)+1+21)<>3,"",DATE($D$4,3,1)-WEEKDAY(DATE($D$4,3,1),2)+1+21) | S28: =IF(MONTH(DATE($D$4,3,1)-WEEKDAY(DATE($D$4,3,1),2)+1+22)<>3,"",DATE($D$4,3,1)-WEEKDAY(DATE($D$4,3,1),2)+1+22) | T28: =IF(MONTH(DATE($D$4,3,1)-WEEKDAY(DATE($D$4,3,1),2)+1+23)<>3,"",DATE($D$4,3,1)-WEEKDAY(DATE($D$4,3,1),2)+1+23) | U28: =IF(MONTH(DATE($D$4,3,1)-WEEKDAY(DATE($D$4,3,1),2)+1+24)<>3,"",DATE($D$4,3,1)-WEEKDAY(DATE($D$4,3,1),2)+1+24) | V28: =IF(MONTH(DATE($D$4,3,1)-WEEKDAY(DATE($D$4,3,1),2)+1+25)<>3,"",DATE($D$4,3,1)-WEEKDAY(DATE($D$4,3,1),2)+1+25) | W28: =IF(MONTH(DATE($D$4,3,1)-WEEKDAY(DATE($D$4,3,1),2)+1+26)<>3,"",DATE($D$4,3,1)-WEEKDAY(DATE($D$4,3,1),2)+1+26) | X28: =IF(MONTH(DATE($D$4,3,1)-WEEKDAY(DATE($D$4,3,1),2)+1+27)<>3,"",DATE($D$4,3,1)-WEEKDAY(DATE($D$4,3,1),2)+1+27)
B29: =IF(MONTH(DATE($D$4,1,1)-WEEKDAY(DATE($D$4,1,1),2)+1+28)<>1,"",DATE($D$4,1,1)-WEEKDAY(DATE($D$4,1,1),2)+1+28) | C29: =IF(MONTH(DATE($D$4,1,1)-WEEKDAY(DATE($D$4,1,1),2)+1+29)<>1,"",DATE($D$4,1,1)-WEEKDAY(DATE($D$4,1,1),2)+1+29) | D29: =IF(MONTH(DATE($D$4,1,1)-WEEKDAY(DATE($D$4,1,1),2)+1+30)<>1,"",DATE($D$4,1,1)-WEEKDAY(DATE($D$4,1,1),2)+1+30) | E29: =IF(MONTH(DATE($D$4,1,1)-WEEKDAY(DATE($D$4,1,1),2)+1+31)<>1,"",DATE($D$4,1,1)-WEEKDAY(DATE($D$4,1,1),2)+1+31) | F29: =IF(MONTH(DATE($D$4,1,1)-WEEKDAY(DATE($D$4,1,1),2)+1+32)<>1,"",DATE($D$4,1,1)-WEEKDAY(DATE($D$4,1,1),2)+1+32) | G29: =IF(MONTH(DATE($D$4,1,1)-WEEKDAY(DATE($D$4,1,1),2)+1+33)<>1,"",DATE($D$4,1,1)-WEEKDAY(DATE($D$4,1,1),2)+1+33) | H29: =IF(MONTH(DATE($D$4,1,1)-WEEKDAY(DATE($D$4,1,1),2)+1+34)<>1,"",DATE($D$4,1,1)-WEEKDAY(DATE($D$4,1,1),2)+1+34) | J29: =IF(MONTH(DATE($D$4,2,1)-WEEKDAY(DATE($D$4,2,1),2)+1+28)<>2,"",DATE($D$4,2,1)-WEEKDAY(DATE($D$4,2,1),2)+1+28) | K29: =IF(MONTH(DATE($D$4,2,1)-WEEKDAY(DATE($D$4,2,1),2)+1+29)<>2,"",DATE($D$4,2,1)-WEEKDAY(DATE($D$4,2,1),2)+1+29) | L29: =IF(MONTH(DATE($D$4,2,1)-WEEKDAY(DATE($D$4,2,1),2)+1+30)<>2,"",DATE($D$4,2,1)-WEEKDAY(DATE($D$4,2,1),2)+1+30) | M29: =IF(MONTH(DATE($D$4,2,1)-WEEKDAY(DATE($D$4,2,1),2)+1+31)<>2,"",DATE($D$4,2,1)-WEEKDAY(DATE($D$4,2,1),2)+1+31) | N29: =IF(MONTH(DATE($D$4,2,1)-WEEKDAY(DATE($D$4,2,1),2)+1+32)<>2,"",DATE($D$4,2,1)-WEEKDAY(DATE($D$4,2,1),2)+1+32) | O29: =IF(MONTH(DATE($D$4,2,1)-WEEKDAY(DATE($D$4,2,1),2)+1+33)<>2,"",DATE($D$4,2,1)-WEEKDAY(DATE($D$4,2,1),2)+1+33) | P29: =IF(MONTH(DATE($D$4,2,1)-WEEKDAY(DATE($D$4,2,1),2)+1+34)<>2,"",DATE($D$4,2,1)-WEEKDAY(DATE($D$4,2,1),2)+1+34) | R29: =IF(MONTH(DATE($D$4,3,1)-WEEKDAY(DATE($D$4,3,1),2)+1+28)<>3,"",DATE($D$4,3,1)-WEEKDAY(DATE($D$4,3,1),2)+1+28) | S29: =IF(MONTH(DATE($D$4,3,1)-WEEKDAY(DATE($D$4,3,1),2)+1+29)<>3,"",DATE($D$4,3,1)-WEEKDAY(DATE($D$4,3,1),2)+1+29) | T29: =IF(MONTH(DATE($D$4,3,1)-WEEKDAY(DATE($D$4,3,1),2)+1+30)<>3,"",DATE($D$4,3,1)-WEEKDAY(DATE($D$4,3,1),2)+1+30) | U29: =IF(MONTH(DATE($D$4,3,1)-WEEKDAY(DATE($D$4,3,1),2)+1+31)<>3,"",DATE($D$4,3,1)-WEEKDAY(DATE($D$4,3,1),2)+1+31) | V29: =IF(MONTH(DATE($D$4,3,1)-WEEKDAY(DATE($D$4,3,1),2)+1+32)<>3,"",DATE($D$4,3,1)-WEEKDAY(DATE($D$4,3,1),2)+1+32) | W29: =IF(MONTH(DATE($D$4,3,1)-WEEKDAY(DATE($D$4,3,1),2)+1+33)<>3,"",DATE($D$4,3,1)-WEEKDAY(DATE($D$4,3,1),2)+1+33) | X29: =IF(MONTH(DATE($D$4,3,1)-WEEKDAY(DATE($D$4,3,1),2)+1+34)<>3,"",DATE($D$4,3,1)-WEEKDAY(DATE($D$4,3,1),2)+1+34)
B30: =IF(MONTH(DATE($D$4,1,1)-WEEKDAY(DATE($D$4,1,1),2)+1+35)<>1,"",DATE($D$4,1,1)-WEEKDAY(DATE($D$4,1,1),2)+1+35) | C30: =IF(MONTH(DATE($D$4,1,1)-WEEKDAY(DATE($D$4,1,1),2)+1+36)<>1,"",DATE($D$4,1,1)-WEEKDAY(DATE($D$4,1,1),2)+1+36) | D30: =IF(MONTH(DATE($D$4,1,1)-WEEKDAY(DATE($D$4,1,1),2)+1+37)<>1,"",DATE($D$4,1,1)-WEEKDAY(DATE($D$4,1,1),2)+1+37) | E30: =IF(MONTH(DATE($D$4,1,1)-WEEKDAY(DATE($D$4,1,1),2)+1+38)<>1,"",DATE($D$4,1,1)-WEEKDAY(DATE($D$4,1,1),2)+1+38) | F30: =IF(MONTH(DATE($D$4,1,1)-WEEKDAY(DATE($D$4,1,1),2)+1+39)<>1,"",DATE($D$4,1,1)-WEEKDAY(DATE($D$4,1,1),2)+1+39) | G30: =IF(MONTH(DATE($D$4,1,1)-WEEKDAY(DATE($D$4,1,1),2)+1+40)<>1,"",DATE($D$4,1,1)-WEEKDAY(DATE($D$4,1,1),2)+1+40) | H30: =IF(MONTH(DATE($D$4,1,1)-WEEKDAY(DATE($D$4,1,1),2)+1+41)<>1,"",DATE($D$4,1,1)-WEEKDAY(DATE($D$4,1,1),2)+1+41) | J30: =IF(MONTH(DATE($D$4,2,1)-WEEKDAY(DATE($D$4,2,1),2)+1+35)<>2,"",DATE($D$4,2,1)-WEEKDAY(DATE($D$4,2,1),2)+1+35) | K30: =IF(MONTH(DATE($D$4,2,1)-WEEKDAY(DATE($D$4,2,1),2)+1+36)<>2,"",DATE($D$4,2,1)-WEEKDAY(DATE($D$4,2,1),2)+1+36) | L30: =IF(MONTH(DATE($D$4,2,1)-WEEKDAY(DATE($D$4,2,1),2)+1+37)<>2,"",DATE($D$4,2,1)-WEEKDAY(DATE($D$4,2,1),2)+1+37) | M30: =IF(MONTH(DATE($D$4,2,1)-WEEKDAY(DATE($D$4,2,1),2)+1+38)<>2,"",DATE($D$4,2,1)-WEEKDAY(DATE($D$4,2,1),2)+1+38) | N30: =IF(MONTH(DATE($D$4,2,1)-WEEKDAY(DATE($D$4,2,1),2)+1+39)<>2,"",DATE($D$4,2,1)-WEEKDAY(DATE($D$4,2,1),2)+1+39) | O30: =IF(MONTH(DATE($D$4,2,1)-WEEKDAY(DATE($D$4,2,1),2)+1+40)<>2,"",DATE($D$4,2,1)-WEEKDAY(DATE($D$4,2,1),2)+1+40) | P30: =IF(MONTH(DATE($D$4,2,1)-WEEKDAY(DATE($D$4,2,1),2)+1+41)<>2,"",DATE($D$4,2,1)-WEEKDAY(DATE($D$4,2,1),2)+1+41) | R30: =IF(MONTH(DATE($D$4,3,1)-WEEKDAY(DATE($D$4,3,1),2)+1+35)<>3,"",DATE($D$4,3,1)-WEEKDAY(DATE($D$4,3,1),2)+1+35) | S30: =IF(MONTH(DATE($D$4,3,1)-WEEKDAY(DATE($D$4,3,1),2)+1+36)<>3,"",DATE($D$4,3,1)-WEEKDAY(DATE($D$4,3,1),2)+1+36) | T30: =IF(MONTH(DATE($D$4,3,1)-WEEKDAY(DATE($D$4,3,1),2)+1+37)<>3,"",DATE($D$4,3,1)-WEEKDAY(DATE($D$4,3,1),2)+1+37) | U30: =IF(MONTH(DATE($D$4,3,1)-WEEKDAY(DATE($D$4,3,1),2)+1+38)<>3,"",DATE($D$4,3,1)-WEEKDAY(DATE($D$4,3,1),2)+1+38) | V30: =IF(MONTH(DATE($D$4,3,1)-WEEKDAY(DATE($D$4,3,1),2)+1+39)<>3,"",DATE($D$4,3,1)-WEEKDAY(DATE($D$4,3,1),2)+1+39) | W30: =IF(MONTH(DATE($D$4,3,1)-WEEKDAY(DATE($D$4,3,1),2)+1+40)<>3,"",DATE($D$4,3,1)-WEEKDAY(DATE($D$4,3,1),2)+1+40) | X30: =IF(MONTH(DATE($D$4,3,1)-WEEKDAY(DATE($D$4,3,1),2)+1+41)<>3,"",DATE($D$4,3,1)-WEEKDAY(DATE($D$4,3,1),2)+1+41)
B32: ="ABRIL "&$D$4 | G32: =IF(COUNTIFS($B$62:$B$211,">="&DATE($D$4,4,1),$B$62:$B$211,"<="&EOMONTH(DATE($D$4,4,1),0),$V$62:$V$211,"<>4 · Cancelada")=1,"1 cita",COUNTIFS($B$62:$B$211,">="&DATE($D$4,4,1),$B$62:$B$211,"<="&EOMONTH(DATE($D$4,4,1),0),$V$62:$V$211,"<>4 · Cancelada")&" citas") | J32: ="MAYO "&$D$4 | O32: =IF(COUNTIFS($B$62:$B$211,">="&DATE($D$4,5,1),$B$62:$B$211,"<="&EOMONTH(DATE($D$4,5,1),0),$V$62:$V$211,"<>4 · Cancelada")=1,"1 cita",COUNTIFS($B$62:$B$211,">="&DATE($D$4,5,1),$B$62:$B$211,"<="&EOMONTH(DATE($D$4,5,1),0),$V$62:$V$211,"<>4 · Cancelada")&" citas") | R32: ="JUNIO "&$D$4 | W32: =IF(COUNTIFS($B$62:$B$211,">="&DATE($D$4,6,1),$B$62:$B$211,"<="&EOMONTH(DATE($D$4,6,1),0),$V$62:$V$211,"<>4 · Cancelada")=1,"1 cita",COUNTIFS($B$62:$B$211,">="&DATE($D$4,6,1),$B$62:$B$211,"<="&EOMONTH(DATE($D$4,6,1),0),$V$62:$V$211,"<>4 · Cancelada")&" citas")
B33: L | C33: M | D33: X | E33: J | F33: V | G33: S | H33: D | J33: L | K33: M | L33: X | M33: J | N33: V | O33: S | P33: D | R33: L | S33: M | T33: X | U33: J | V33: V | W33: S | X33: D
B34: =IF(MONTH(DATE($D$4,4,1)-WEEKDAY(DATE($D$4,4,1),2)+1+0)<>4,"",DATE($D$4,4,1)-WEEKDAY(DATE($D$4,4,1),2)+1+0) | C34: =IF(MONTH(DATE($D$4,4,1)-WEEKDAY(DATE($D$4,4,1),2)+1+1)<>4,"",DATE($D$4,4,1)-WEEKDAY(DATE($D$4,4,1),2)+1+1) | D34: =IF(MONTH(DATE($D$4,4,1)-WEEKDAY(DATE($D$4,4,1),2)+1+2)<>4,"",DATE($D$4,4,1)-WEEKDAY(DATE($D$4,4,1),2)+1+2) | E34: =IF(MONTH(DATE($D$4,4,1)-WEEKDAY(DATE($D$4,4,1),2)+1+3)<>4,"",DATE($D$4,4,1)-WEEKDAY(DATE($D$4,4,1),2)+1+3) | F34: =IF(MONTH(DATE($D$4,4,1)-WEEKDAY(DATE($D$4,4,1),2)+1+4)<>4,"",DATE($D$4,4,1)-WEEKDAY(DATE($D$4,4,1),2)+1+4) | G34: =IF(MONTH(DATE($D$4,4,1)-WEEKDAY(DATE($D$4,4,1),2)+1+5)<>4,"",DATE($D$4,4,1)-WEEKDAY(DATE($D$4,4,1),2)+1+5) | H34: =IF(MONTH(DATE($D$4,4,1)-WEEKDAY(DATE($D$4,4,1),2)+1+6)<>4,"",DATE($D$4,4,1)-WEEKDAY(DATE($D$4,4,1),2)+1+6) | J34: =IF(MONTH(DATE($D$4,5,1)-WEEKDAY(DATE($D$4,5,1),2)+1+0)<>5,"",DATE($D$4,5,1)-WEEKDAY(DATE($D$4,5,1),2)+1+0) | K34: =IF(MONTH(DATE($D$4,5,1)-WEEKDAY(DATE($D$4,5,1),2)+1+1)<>5,"",DATE($D$4,5,1)-WEEKDAY(DATE($D$4,5,1),2)+1+1) | L34: =IF(MONTH(DATE($D$4,5,1)-WEEKDAY(DATE($D$4,5,1),2)+1+2)<>5,"",DATE($D$4,5,1)-WEEKDAY(DATE($D$4,5,1),2)+1+2) | M34: =IF(MONTH(DATE($D$4,5,1)-WEEKDAY(DATE($D$4,5,1),2)+1+3)<>5,"",DATE($D$4,5,1)-WEEKDAY(DATE($D$4,5,1),2)+1+3) | N34: =IF(MONTH(DATE($D$4,5,1)-WEEKDAY(DATE($D$4,5,1),2)+1+4)<>5,"",DATE($D$4,5,1)-WEEKDAY(DATE($D$4,5,1),2)+1+4) | O34: =IF(MONTH(DATE($D$4,5,1)-WEEKDAY(DATE($D$4,5,1),2)+1+5)<>5,"",DATE($D$4,5,1)-WEEKDAY(DATE($D$4,5,1),2)+1+5) | P34: =IF(MONTH(DATE($D$4,5,1)-WEEKDAY(DATE($D$4,5,1),2)+1+6)<>5,"",DATE($D$4,5,1)-WEEKDAY(DATE($D$4,5,1),2)+1+6) | R34: =IF(MONTH(DATE($D$4,6,1)-WEEKDAY(DATE($D$4,6,1),2)+1+0)<>6,"",DATE($D$4,6,1)-WEEKDAY(DATE($D$4,6,1),2)+1+0) | S34: =IF(MONTH(DATE($D$4,6,1)-WEEKDAY(DATE($D$4,6,1),2)+1+1)<>6,"",DATE($D$4,6,1)-WEEKDAY(DATE($D$4,6,1),2)+1+1) | T34: =IF(MONTH(DATE($D$4,6,1)-WEEKDAY(DATE($D$4,6,1),2)+1+2)<>6,"",DATE($D$4,6,1)-WEEKDAY(DATE($D$4,6,1),2)+1+2) | U34: =IF(MONTH(DATE($D$4,6,1)-WEEKDAY(DATE($D$4,6,1),2)+1+3)<>6,"",DATE($D$4,6,1)-WEEKDAY(DATE($D$4,6,1),2)+1+3) | V34: =IF(MONTH(DATE($D$4,6,1)-WEEKDAY(DATE($D$4,6,1),2)+1+4)<>6,"",DATE($D$4,6,1)-WEEKDAY(DATE($D$4,6,1),2)+1+4) | W34: =IF(MONTH(DATE($D$4,6,1)-WEEKDAY(DATE($D$4,6,1),2)+1+5)<>6,"",DATE($D$4,6,1)-WEEKDAY(DATE($D$4,6,1),2)+1+5) | X34: =IF(MONTH(DATE($D$4,6,1)-WEEKDAY(DATE($D$4,6,1),2)+1+6)<>6,"",DATE($D$4,6,1)-WEEKDAY(DATE($D$4,6,1),2)+1+6)
B35: =IF(MONTH(DATE($D$4,4,1)-WEEKDAY(DATE($D$4,4,1),2)+1+7)<>4,"",DATE($D$4,4,1)-WEEKDAY(DATE($D$4,4,1),2)+1+7) | C35: =IF(MONTH(DATE($D$4,4,1)-WEEKDAY(DATE($D$4,4,1),2)+1+8)<>4,"",DATE($D$4,4,1)-WEEKDAY(DATE($D$4,4,1),2)+1+8) | D35: =IF(MONTH(DATE($D$4,4,1)-WEEKDAY(DATE($D$4,4,1),2)+1+9)<>4,"",DATE($D$4,4,1)-WEEKDAY(DATE($D$4,4,1),2)+1+9) | E35: =IF(MONTH(DATE($D$4,4,1)-WEEKDAY(DATE($D$4,4,1),2)+1+10)<>4,"",DATE($D$4,4,1)-WEEKDAY(DATE($D$4,4,1),2)+1+10) | F35: =IF(MONTH(DATE($D$4,4,1)-WEEKDAY(DATE($D$4,4,1),2)+1+11)<>4,"",DATE($D$4,4,1)-WEEKDAY(DATE($D$4,4,1),2)+1+11) | G35: =IF(MONTH(DATE($D$4,4,1)-WEEKDAY(DATE($D$4,4,1),2)+1+12)<>4,"",DATE($D$4,4,1)-WEEKDAY(DATE($D$4,4,1),2)+1+12) | H35: =IF(MONTH(DATE($D$4,4,1)-WEEKDAY(DATE($D$4,4,1),2)+1+13)<>4,"",DATE($D$4,4,1)-WEEKDAY(DATE($D$4,4,1),2)+1+13) | J35: =IF(MONTH(DATE($D$4,5,1)-WEEKDAY(DATE($D$4,5,1),2)+1+7)<>5,"",DATE($D$4,5,1)-WEEKDAY(DATE($D$4,5,1),2)+1+7) | K35: =IF(MONTH(DATE($D$4,5,1)-WEEKDAY(DATE($D$4,5,1),2)+1+8)<>5,"",DATE($D$4,5,1)-WEEKDAY(DATE($D$4,5,1),2)+1+8) | L35: =IF(MONTH(DATE($D$4,5,1)-WEEKDAY(DATE($D$4,5,1),2)+1+9)<>5,"",DATE($D$4,5,1)-WEEKDAY(DATE($D$4,5,1),2)+1+9) | M35: =IF(MONTH(DATE($D$4,5,1)-WEEKDAY(DATE($D$4,5,1),2)+1+10)<>5,"",DATE($D$4,5,1)-WEEKDAY(DATE($D$4,5,1),2)+1+10) | N35: =IF(MONTH(DATE($D$4,5,1)-WEEKDAY(DATE($D$4,5,1),2)+1+11)<>5,"",DATE($D$4,5,1)-WEEKDAY(DATE($D$4,5,1),2)+1+11) | O35: =IF(MONTH(DATE($D$4,5,1)-WEEKDAY(DATE($D$4,5,1),2)+1+12)<>5,"",DATE($D$4,5,1)-WEEKDAY(DATE($D$4,5,1),2)+1+12) | P35: =IF(MONTH(DATE($D$4,5,1)-WEEKDAY(DATE($D$4,5,1),2)+1+13)<>5,"",DATE($D$4,5,1)-WEEKDAY(DATE($D$4,5,1),2)+1+13) | R35: =IF(MONTH(DATE($D$4,6,1)-WEEKDAY(DATE($D$4,6,1),2)+1+7)<>6,"",DATE($D$4,6,1)-WEEKDAY(DATE($D$4,6,1),2)+1+7) | S35: =IF(MONTH(DATE($D$4,6,1)-WEEKDAY(DATE($D$4,6,1),2)+1+8)<>6,"",DATE($D$4,6,1)-WEEKDAY(DATE($D$4,6,1),2)+1+8) | T35: =IF(MONTH(DATE($D$4,6,1)-WEEKDAY(DATE($D$4,6,1),2)+1+9)<>6,"",DATE($D$4,6,1)-WEEKDAY(DATE($D$4,6,1),2)+1+9) | U35: =IF(MONTH(DATE($D$4,6,1)-WEEKDAY(DATE($D$4,6,1),2)+1+10)<>6,"",DATE($D$4,6,1)-WEEKDAY(DATE($D$4,6,1),2)+1+10) | V35: =IF(MONTH(DATE($D$4,6,1)-WEEKDAY(DATE($D$4,6,1),2)+1+11)<>6,"",DATE($D$4,6,1)-WEEKDAY(DATE($D$4,6,1),2)+1+11) | W35: =IF(MONTH(DATE($D$4,6,1)-WEEKDAY(DATE($D$4,6,1),2)+1+12)<>6,"",DATE($D$4,6,1)-WEEKDAY(DATE($D$4,6,1),2)+1+12) | X35: =IF(MONTH(DATE($D$4,6,1)-WEEKDAY(DATE($D$4,6,1),2)+1+13)<>6,"",DATE($D$4,6,1)-WEEKDAY(DATE($D$4,6,1),2)+1+13)
B36: =IF(MONTH(DATE($D$4,4,1)-WEEKDAY(DATE($D$4,4,1),2)+1+14)<>4,"",DATE($D$4,4,1)-WEEKDAY(DATE($D$4,4,1),2)+1+14) | C36: =IF(MONTH(DATE($D$4,4,1)-WEEKDAY(DATE($D$4,4,1),2)+1+15)<>4,"",DATE($D$4,4,1)-WEEKDAY(DATE($D$4,4,1),2)+1+15) | D36: =IF(MONTH(DATE($D$4,4,1)-WEEKDAY(DATE($D$4,4,1),2)+1+16)<>4,"",DATE($D$4,4,1)-WEEKDAY(DATE($D$4,4,1),2)+1+16) | E36: =IF(MONTH(DATE($D$4,4,1)-WEEKDAY(DATE($D$4,4,1),2)+1+17)<>4,"",DATE($D$4,4,1)-WEEKDAY(DATE($D$4,4,1),2)+1+17) | F36: =IF(MONTH(DATE($D$4,4,1)-WEEKDAY(DATE($D$4,4,1),2)+1+18)<>4,"",DATE($D$4,4,1)-WEEKDAY(DATE($D$4,4,1),2)+1+18) | G36: =IF(MONTH(DATE($D$4,4,1)-WEEKDAY(DATE($D$4,4,1),2)+1+19)<>4,"",DATE($D$4,4,1)-WEEKDAY(DATE($D$4,4,1),2)+1+19) | H36: =IF(MONTH(DATE($D$4,4,1)-WEEKDAY(DATE($D$4,4,1),2)+1+20)<>4,"",DATE($D$4,4,1)-WEEKDAY(DATE($D$4,4,1),2)+1+20) | J36: =IF(MONTH(DATE($D$4,5,1)-WEEKDAY(DATE($D$4,5,1),2)+1+14)<>5,"",DATE($D$4,5,1)-WEEKDAY(DATE($D$4,5,1),2)+1+14) | K36: =IF(MONTH(DATE($D$4,5,1)-WEEKDAY(DATE($D$4,5,1),2)+1+15)<>5,"",DATE($D$4,5,1)-WEEKDAY(DATE($D$4,5,1),2)+1+15) | L36: =IF(MONTH(DATE($D$4,5,1)-WEEKDAY(DATE($D$4,5,1),2)+1+16)<>5,"",DATE($D$4,5,1)-WEEKDAY(DATE($D$4,5,1),2)+1+16) | M36: =IF(MONTH(DATE($D$4,5,1)-WEEKDAY(DATE($D$4,5,1),2)+1+17)<>5,"",DATE($D$4,5,1)-WEEKDAY(DATE($D$4,5,1),2)+1+17) | N36: =IF(MONTH(DATE($D$4,5,1)-WEEKDAY(DATE($D$4,5,1),2)+1+18)<>5,"",DATE($D$4,5,1)-WEEKDAY(DATE($D$4,5,1),2)+1+18) | O36: =IF(MONTH(DATE($D$4,5,1)-WEEKDAY(DATE($D$4,5,1),2)+1+19)<>5,"",DATE($D$4,5,1)-WEEKDAY(DATE($D$4,5,1),2)+1+19) | P36: =IF(MONTH(DATE($D$4,5,1)-WEEKDAY(DATE($D$4,5,1),2)+1+20)<>5,"",DATE($D$4,5,1)-WEEKDAY(DATE($D$4,5,1),2)+1+20) | R36: =IF(MONTH(DATE($D$4,6,1)-WEEKDAY(DATE($D$4,6,1),2)+1+14)<>6,"",DATE($D$4,6,1)-WEEKDAY(DATE($D$4,6,1),2)+1+14) | S36: =IF(MONTH(DATE($D$4,6,1)-WEEKDAY(DATE($D$4,6,1),2)+1+15)<>6,"",DATE($D$4,6,1)-WEEKDAY(DATE($D$4,6,1),2)+1+15) | T36: =IF(MONTH(DATE($D$4,6,1)-WEEKDAY(DATE($D$4,6,1),2)+1+16)<>6,"",DATE($D$4,6,1)-WEEKDAY(DATE($D$4,6,1),2)+1+16) | U36: =IF(MONTH(DATE($D$4,6,1)-WEEKDAY(DATE($D$4,6,1),2)+1+17)<>6,"",DATE($D$4,6,1)-WEEKDAY(DATE($D$4,6,1),2)+1+17) | V36: =IF(MONTH(DATE($D$4,6,1)-WEEKDAY(DATE($D$4,6,1),2)+1+18)<>6,"",DATE($D$4,6,1)-WEEKDAY(DATE($D$4,6,1),2)+1+18) | W36: =IF(MONTH(DATE($D$4,6,1)-WEEKDAY(DATE($D$4,6,1),2)+1+19)<>6,"",DATE($D$4,6,1)-WEEKDAY(DATE($D$4,6,1),2)+1+19) | X36: =IF(MONTH(DATE($D$4,6,1)-WEEKDAY(DATE($D$4,6,1),2)+1+20)<>6,"",DATE($D$4,6,1)-WEEKDAY(DATE($D$4,6,1),2)+1+20)
B37: =IF(MONTH(DATE($D$4,4,1)-WEEKDAY(DATE($D$4,4,1),2)+1+21)<>4,"",DATE($D$4,4,1)-WEEKDAY(DATE($D$4,4,1),2)+1+21) | C37: =IF(MONTH(DATE($D$4,4,1)-WEEKDAY(DATE($D$4,4,1),2)+1+22)<>4,"",DATE($D$4,4,1)-WEEKDAY(DATE($D$4,4,1),2)+1+22) | D37: =IF(MONTH(DATE($D$4,4,1)-WEEKDAY(DATE($D$4,4,1),2)+1+23)<>4,"",DATE($D$4,4,1)-WEEKDAY(DATE($D$4,4,1),2)+1+23) | E37: =IF(MONTH(DATE($D$4,4,1)-WEEKDAY(DATE($D$4,4,1),2)+1+24)<>4,"",DATE($D$4,4,1)-WEEKDAY(DATE($D$4,4,1),2)+1+24) | F37: =IF(MONTH(DATE($D$4,4,1)-WEEKDAY(DATE($D$4,4,1),2)+1+25)<>4,"",DATE($D$4,4,1)-WEEKDAY(DATE($D$4,4,1),2)+1+25) | G37: =IF(MONTH(DATE($D$4,4,1)-WEEKDAY(DATE($D$4,4,1),2)+1+26)<>4,"",DATE($D$4,4,1)-WEEKDAY(DATE($D$4,4,1),2)+1+26) | H37: =IF(MONTH(DATE($D$4,4,1)-WEEKDAY(DATE($D$4,4,1),2)+1+27)<>4,"",DATE($D$4,4,1)-WEEKDAY(DATE($D$4,4,1),2)+1+27) | J37: =IF(MONTH(DATE($D$4,5,1)-WEEKDAY(DATE($D$4,5,1),2)+1+21)<>5,"",DATE($D$4,5,1)-WEEKDAY(DATE($D$4,5,1),2)+1+21) | K37: =IF(MONTH(DATE($D$4,5,1)-WEEKDAY(DATE($D$4,5,1),2)+1+22)<>5,"",DATE($D$4,5,1)-WEEKDAY(DATE($D$4,5,1),2)+1+22) | L37: =IF(MONTH(DATE($D$4,5,1)-WEEKDAY(DATE($D$4,5,1),2)+1+23)<>5,"",DATE($D$4,5,1)-WEEKDAY(DATE($D$4,5,1),2)+1+23) | M37: =IF(MONTH(DATE($D$4,5,1)-WEEKDAY(DATE($D$4,5,1),2)+1+24)<>5,"",DATE($D$4,5,1)-WEEKDAY(DATE($D$4,5,1),2)+1+24) | N37: =IF(MONTH(DATE($D$4,5,1)-WEEKDAY(DATE($D$4,5,1),2)+1+25)<>5,"",DATE($D$4,5,1)-WEEKDAY(DATE($D$4,5,1),2)+1+25) | O37: =IF(MONTH(DATE($D$4,5,1)-WEEKDAY(DATE($D$4,5,1),2)+1+26)<>5,"",DATE($D$4,5,1)-WEEKDAY(DATE($D$4,5,1),2)+1+26) | P37: =IF(MONTH(DATE($D$4,5,1)-WEEKDAY(DATE($D$4,5,1),2)+1+27)<>5,"",DATE($D$4,5,1)-WEEKDAY(DATE($D$4,5,1),2)+1+27) | R37: =IF(MONTH(DATE($D$4,6,1)-WEEKDAY(DATE($D$4,6,1),2)+1+21)<>6,"",DATE($D$4,6,1)-WEEKDAY(DATE($D$4,6,1),2)+1+21) | S37: =IF(MONTH(DATE($D$4,6,1)-WEEKDAY(DATE($D$4,6,1),2)+1+22)<>6,"",DATE($D$4,6,1)-WEEKDAY(DATE($D$4,6,1),2)+1+22) | T37: =IF(MONTH(DATE($D$4,6,1)-WEEKDAY(DATE($D$4,6,1),2)+1+23)<>6,"",DATE($D$4,6,1)-WEEKDAY(DATE($D$4,6,1),2)+1+23) | U37: =IF(MONTH(DATE($D$4,6,1)-WEEKDAY(DATE($D$4,6,1),2)+1+24)<>6,"",DATE($D$4,6,1)-WEEKDAY(DATE($D$4,6,1),2)+1+24) | V37: =IF(MONTH(DATE($D$4,6,1)-WEEKDAY(DATE($D$4,6,1),2)+1+25)<>6,"",DATE($D$4,6,1)-WEEKDAY(DATE($D$4,6,1),2)+1+25) | W37: =IF(MONTH(DATE($D$4,6,1)-WEEKDAY(DATE($D$4,6,1),2)+1+26)<>6,"",DATE($D$4,6,1)-WEEKDAY(DATE($D$4,6,1),2)+1+26) | X37: =IF(MONTH(DATE($D$4,6,1)-WEEKDAY(DATE($D$4,6,1),2)+1+27)<>6,"",DATE($D$4,6,1)-WEEKDAY(DATE($D$4,6,1),2)+1+27)
B38: =IF(MONTH(DATE($D$4,4,1)-WEEKDAY(DATE($D$4,4,1),2)+1+28)<>4,"",DATE($D$4,4,1)-WEEKDAY(DATE($D$4,4,1),2)+1+28) | C38: =IF(MONTH(DATE($D$4,4,1)-WEEKDAY(DATE($D$4,4,1),2)+1+29)<>4,"",DATE($D$4,4,1)-WEEKDAY(DATE($D$4,4,1),2)+1+29) | D38: =IF(MONTH(DATE($D$4,4,1)-WEEKDAY(DATE($D$4,4,1),2)+1+30)<>4,"",DATE($D$4,4,1)-WEEKDAY(DATE($D$4,4,1),2)+1+30) | E38: =IF(MONTH(DATE($D$4,4,1)-WEEKDAY(DATE($D$4,4,1),2)+1+31)<>4,"",DATE($D$4,4,1)-WEEKDAY(DATE($D$4,4,1),2)+1+31) | F38: =IF(MONTH(DATE($D$4,4,1)-WEEKDAY(DATE($D$4,4,1),2)+1+32)<>4,"",DATE($D$4,4,1)-WEEKDAY(DATE($D$4,4,1),2)+1+32) | G38: =IF(MONTH(DATE($D$4,4,1)-WEEKDAY(DATE($D$4,4,1),2)+1+33)<>4,"",DATE($D$4,4,1)-WEEKDAY(DATE($D$4,4,1),2)+1+33) | H38: =IF(MONTH(DATE($D$4,4,1)-WEEKDAY(DATE($D$4,4,1),2)+1+34)<>4,"",DATE($D$4,4,1)-WEEKDAY(DATE($D$4,4,1),2)+1+34) | J38: =IF(MONTH(DATE($D$4,5,1)-WEEKDAY(DATE($D$4,5,1),2)+1+28)<>5,"",DATE($D$4,5,1)-WEEKDAY(DATE($D$4,5,1),2)+1+28) | K38: =IF(MONTH(DATE($D$4,5,1)-WEEKDAY(DATE($D$4,5,1),2)+1+29)<>5,"",DATE($D$4,5,1)-WEEKDAY(DATE($D$4,5,1),2)+1+29) | L38: =IF(MONTH(DATE($D$4,5,1)-WEEKDAY(DATE($D$4,5,1),2)+1+30)<>5,"",DATE($D$4,5,1)-WEEKDAY(DATE($D$4,5,1),2)+1+30) | M38: =IF(MONTH(DATE($D$4,5,1)-WEEKDAY(DATE($D$4,5,1),2)+1+31)<>5,"",DATE($D$4,5,1)-WEEKDAY(DATE($D$4,5,1),2)+1+31) | N38: =IF(MONTH(DATE($D$4,5,1)-WEEKDAY(DATE($D$4,5,1),2)+1+32)<>5,"",DATE($D$4,5,1)-WEEKDAY(DATE($D$4,5,1),2)+1+32) | O38: =IF(MONTH(DATE($D$4,5,1)-WEEKDAY(DATE($D$4,5,1),2)+1+33)<>5,"",DATE($D$4,5,1)-WEEKDAY(DATE($D$4,5,1),2)+1+33) | P38: =IF(MONTH(DATE($D$4,5,1)-WEEKDAY(DATE($D$4,5,1),2)+1+34)<>5,"",DATE($D$4,5,1)-WEEKDAY(DATE($D$4,5,1),2)+1+34) | R38: =IF(MONTH(DATE($D$4,6,1)-WEEKDAY(DATE($D$4,6,1),2)+1+28)<>6,"",DATE($D$4,6,1)-WEEKDAY(DATE($D$4,6,1),2)+1+28) | S38: =IF(MONTH(DATE($D$4,6,1)-WEEKDAY(DATE($D$4,6,1),2)+1+29)<>6,"",DATE($D$4,6,1)-WEEKDAY(DATE($D$4,6,1),2)+1+29) | T38: =IF(MONTH(DATE($D$4,6,1)-WEEKDAY(DATE($D$4,6,1),2)+1+30)<>6,"",DATE($D$4,6,1)-WEEKDAY(DATE($D$4,6,1),2)+1+30) | U38: =IF(MONTH(DATE($D$4,6,1)-WEEKDAY(DATE($D$4,6,1),2)+1+31)<>6,"",DATE($D$4,6,1)-WEEKDAY(DATE($D$4,6,1),2)+1+31) | V38: =IF(MONTH(DATE($D$4,6,1)-WEEKDAY(DATE($D$4,6,1),2)+1+32)<>6,"",DATE($D$4,6,1)-WEEKDAY(DATE($D$4,6,1),2)+1+32) | W38: =IF(MONTH(DATE($D$4,6,1)-WEEKDAY(DATE($D$4,6,1),2)+1+33)<>6,"",DATE($D$4,6,1)-WEEKDAY(DATE($D$4,6,1),2)+1+33) | X38: =IF(MONTH(DATE($D$4,6,1)-WEEKDAY(DATE($D$4,6,1),2)+1+34)<>6,"",DATE($D$4,6,1)-WEEKDAY(DATE($D$4,6,1),2)+1+34)
B39: =IF(MONTH(DATE($D$4,4,1)-WEEKDAY(DATE($D$4,4,1),2)+1+35)<>4,"",DATE($D$4,4,1)-WEEKDAY(DATE($D$4,4,1),2)+1+35) | C39: =IF(MONTH(DATE($D$4,4,1)-WEEKDAY(DATE($D$4,4,1),2)+1+36)<>4,"",DATE($D$4,4,1)-WEEKDAY(DATE($D$4,4,1),2)+1+36) | D39: =IF(MONTH(DATE($D$4,4,1)-WEEKDAY(DATE($D$4,4,1),2)+1+37)<>4,"",DATE($D$4,4,1)-WEEKDAY(DATE($D$4,4,1),2)+1+37) | E39: =IF(MONTH(DATE($D$4,4,1)-WEEKDAY(DATE($D$4,4,1),2)+1+38)<>4,"",DATE($D$4,4,1)-WEEKDAY(DATE($D$4,4,1),2)+1+38) | F39: =IF(MONTH(DATE($D$4,4,1)-WEEKDAY(DATE($D$4,4,1),2)+1+39)<>4,"",DATE($D$4,4,1)-WEEKDAY(DATE($D$4,4,1),2)+1+39) | G39: =IF(MONTH(DATE($D$4,4,1)-WEEKDAY(DATE($D$4,4,1),2)+1+40)<>4,"",DATE($D$4,4,1)-WEEKDAY(DATE($D$4,4,1),2)+1+40) | H39: =IF(MONTH(DATE($D$4,4,1)-WEEKDAY(DATE($D$4,4,1),2)+1+41)<>4,"",DATE($D$4,4,1)-WEEKDAY(DATE($D$4,4,1),2)+1+41) | J39: =IF(MONTH(DATE($D$4,5,1)-WEEKDAY(DATE($D$4,5,1),2)+1+35)<>5,"",DATE($D$4,5,1)-WEEKDAY(DATE($D$4,5,1),2)+1+35) | K39: =IF(MONTH(DATE($D$4,5,1)-WEEKDAY(DATE($D$4,5,1),2)+1+36)<>5,"",DATE($D$4,5,1)-WEEKDAY(DATE($D$4,5,1),2)+1+36) | L39: =IF(MONTH(DATE($D$4,5,1)-WEEKDAY(DATE($D$4,5,1),2)+1+37)<>5,"",DATE($D$4,5,1)-WEEKDAY(DATE($D$4,5,1),2)+1+37) | M39: =IF(MONTH(DATE($D$4,5,1)-WEEKDAY(DATE($D$4,5,1),2)+1+38)<>5,"",DATE($D$4,5,1)-WEEKDAY(DATE($D$4,5,1),2)+1+38) | N39: =IF(MONTH(DATE($D$4,5,1)-WEEKDAY(DATE($D$4,5,1),2)+1+39)<>5,"",DATE($D$4,5,1)-WEEKDAY(DATE($D$4,5,1),2)+1+39) | O39: =IF(MONTH(DATE($D$4,5,1)-WEEKDAY(DATE($D$4,5,1),2)+1+40)<>5,"",DATE($D$4,5,1)-WEEKDAY(DATE($D$4,5,1),2)+1+40) | P39: =IF(MONTH(DATE($D$4,5,1)-WEEKDAY(DATE($D$4,5,1),2)+1+41)<>5,"",DATE($D$4,5,1)-WEEKDAY(DATE($D$4,5,1),2)+1+41) | R39: =IF(MONTH(DATE($D$4,6,1)-WEEKDAY(DATE($D$4,6,1),2)+1+35)<>6,"",DATE($D$4,6,1)-WEEKDAY(DATE($D$4,6,1),2)+1+35) | S39: =IF(MONTH(DATE($D$4,6,1)-WEEKDAY(DATE($D$4,6,1),2)+1+36)<>6,"",DATE($D$4,6,1)-WEEKDAY(DATE($D$4,6,1),2)+1+36) | T39: =IF(MONTH(DATE($D$4,6,1)-WEEKDAY(DATE($D$4,6,1),2)+1+37)<>6,"",DATE($D$4,6,1)-WEEKDAY(DATE($D$4,6,1),2)+1+37) | U39: =IF(MONTH(DATE($D$4,6,1)-WEEKDAY(DATE($D$4,6,1),2)+1+38)<>6,"",DATE($D$4,6,1)-WEEKDAY(DATE($D$4,6,1),2)+1+38) | V39: =IF(MONTH(DATE($D$4,6,1)-WEEKDAY(DATE($D$4,6,1),2)+1+39)<>6,"",DATE($D$4,6,1)-WEEKDAY(DATE($D$4,6,1),2)+1+39) | W39: =IF(MONTH(DATE($D$4,6,1)-WEEKDAY(DATE($D$4,6,1),2)+1+40)<>6,"",DATE($D$4,6,1)-WEEKDAY(DATE($D$4,6,1),2)+1+40) | X39: =IF(MONTH(DATE($D$4,6,1)-WEEKDAY(DATE($D$4,6,1),2)+1+41)<>6,"",DATE($D$4,6,1)-WEEKDAY(DATE($D$4,6,1),2)+1+41)
B41: ="JULIO "&$D$4 | G41: =IF(COUNTIFS($B$62:$B$211,">="&DATE($D$4,7,1),$B$62:$B$211,"<="&EOMONTH(DATE($D$4,7,1),0),$V$62:$V$211,"<>4 · Cancelada")=1,"1 cita",COUNTIFS($B$62:$B$211,">="&DATE($D$4,7,1),$B$62:$B$211,"<="&EOMONTH(DATE($D$4,7,1),0),$V$62:$V$211,"<>4 · Cancelada")&" citas") | J41: ="AGOSTO "&$D$4 | O41: =IF(COUNTIFS($B$62:$B$211,">="&DATE($D$4,8,1),$B$62:$B$211,"<="&EOMONTH(DATE($D$4,8,1),0),$V$62:$V$211,"<>4 · Cancelada")=1,"1 cita",COUNTIFS($B$62:$B$211,">="&DATE($D$4,8,1),$B$62:$B$211,"<="&EOMONTH(DATE($D$4,8,1),0),$V$62:$V$211,"<>4 · Cancelada")&" citas") | R41: ="SEPTIEMBRE "&$D$4 | W41: =IF(COUNTIFS($B$62:$B$211,">="&DATE($D$4,9,1),$B$62:$B$211,"<="&EOMONTH(DATE($D$4,9,1),0),$V$62:$V$211,"<>4 · Cancelada")=1,"1 cita",COUNTIFS($B$62:$B$211,">="&DATE($D$4,9,1),$B$62:$B$211,"<="&EOMONTH(DATE($D$4,9,1),0),$V$62:$V$211,"<>4 · Cancelada")&" citas")
B42: L | C42: M | D42: X | E42: J | F42: V | G42: S | H42: D | J42: L | K42: M | L42: X | M42: J | N42: V | O42: S | P42: D | R42: L | S42: M | T42: X | U42: J | V42: V | W42: S | X42: D
B43: =IF(MONTH(DATE($D$4,7,1)-WEEKDAY(DATE($D$4,7,1),2)+1+0)<>7,"",DATE($D$4,7,1)-WEEKDAY(DATE($D$4,7,1),2)+1+0) | C43: =IF(MONTH(DATE($D$4,7,1)-WEEKDAY(DATE($D$4,7,1),2)+1+1)<>7,"",DATE($D$4,7,1)-WEEKDAY(DATE($D$4,7,1),2)+1+1) | D43: =IF(MONTH(DATE($D$4,7,1)-WEEKDAY(DATE($D$4,7,1),2)+1+2)<>7,"",DATE($D$4,7,1)-WEEKDAY(DATE($D$4,7,1),2)+1+2) | E43: =IF(MONTH(DATE($D$4,7,1)-WEEKDAY(DATE($D$4,7,1),2)+1+3)<>7,"",DATE($D$4,7,1)-WEEKDAY(DATE($D$4,7,1),2)+1+3) | F43: =IF(MONTH(DATE($D$4,7,1)-WEEKDAY(DATE($D$4,7,1),2)+1+4)<>7,"",DATE($D$4,7,1)-WEEKDAY(DATE($D$4,7,1),2)+1+4) | G43: =IF(MONTH(DATE($D$4,7,1)-WEEKDAY(DATE($D$4,7,1),2)+1+5)<>7,"",DATE($D$4,7,1)-WEEKDAY(DATE($D$4,7,1),2)+1+5) | H43: =IF(MONTH(DATE($D$4,7,1)-WEEKDAY(DATE($D$4,7,1),2)+1+6)<>7,"",DATE($D$4,7,1)-WEEKDAY(DATE($D$4,7,1),2)+1+6) | J43: =IF(MONTH(DATE($D$4,8,1)-WEEKDAY(DATE($D$4,8,1),2)+1+0)<>8,"",DATE($D$4,8,1)-WEEKDAY(DATE($D$4,8,1),2)+1+0) | K43: =IF(MONTH(DATE($D$4,8,1)-WEEKDAY(DATE($D$4,8,1),2)+1+1)<>8,"",DATE($D$4,8,1)-WEEKDAY(DATE($D$4,8,1),2)+1+1) | L43: =IF(MONTH(DATE($D$4,8,1)-WEEKDAY(DATE($D$4,8,1),2)+1+2)<>8,"",DATE($D$4,8,1)-WEEKDAY(DATE($D$4,8,1),2)+1+2) | M43: =IF(MONTH(DATE($D$4,8,1)-WEEKDAY(DATE($D$4,8,1),2)+1+3)<>8,"",DATE($D$4,8,1)-WEEKDAY(DATE($D$4,8,1),2)+1+3) | N43: =IF(MONTH(DATE($D$4,8,1)-WEEKDAY(DATE($D$4,8,1),2)+1+4)<>8,"",DATE($D$4,8,1)-WEEKDAY(DATE($D$4,8,1),2)+1+4) | O43: =IF(MONTH(DATE($D$4,8,1)-WEEKDAY(DATE($D$4,8,1),2)+1+5)<>8,"",DATE($D$4,8,1)-WEEKDAY(DATE($D$4,8,1),2)+1+5) | P43: =IF(MONTH(DATE($D$4,8,1)-WEEKDAY(DATE($D$4,8,1),2)+1+6)<>8,"",DATE($D$4,8,1)-WEEKDAY(DATE($D$4,8,1),2)+1+6) | R43: =IF(MONTH(DATE($D$4,9,1)-WEEKDAY(DATE($D$4,9,1),2)+1+0)<>9,"",DATE($D$4,9,1)-WEEKDAY(DATE($D$4,9,1),2)+1+0) | S43: =IF(MONTH(DATE($D$4,9,1)-WEEKDAY(DATE($D$4,9,1),2)+1+1)<>9,"",DATE($D$4,9,1)-WEEKDAY(DATE($D$4,9,1),2)+1+1) | T43: =IF(MONTH(DATE($D$4,9,1)-WEEKDAY(DATE($D$4,9,1),2)+1+2)<>9,"",DATE($D$4,9,1)-WEEKDAY(DATE($D$4,9,1),2)+1+2) | U43: =IF(MONTH(DATE($D$4,9,1)-WEEKDAY(DATE($D$4,9,1),2)+1+3)<>9,"",DATE($D$4,9,1)-WEEKDAY(DATE($D$4,9,1),2)+1+3) | V43: =IF(MONTH(DATE($D$4,9,1)-WEEKDAY(DATE($D$4,9,1),2)+1+4)<>9,"",DATE($D$4,9,1)-WEEKDAY(DATE($D$4,9,1),2)+1+4) | W43: =IF(MONTH(DATE($D$4,9,1)-WEEKDAY(DATE($D$4,9,1),2)+1+5)<>9,"",DATE($D$4,9,1)-WEEKDAY(DATE($D$4,9,1),2)+1+5) | X43: =IF(MONTH(DATE($D$4,9,1)-WEEKDAY(DATE($D$4,9,1),2)+1+6)<>9,"",DATE($D$4,9,1)-WEEKDAY(DATE($D$4,9,1),2)+1+6)
B44: =IF(MONTH(DATE($D$4,7,1)-WEEKDAY(DATE($D$4,7,1),2)+1+7)<>7,"",DATE($D$4,7,1)-WEEKDAY(DATE($D$4,7,1),2)+1+7) | C44: =IF(MONTH(DATE($D$4,7,1)-WEEKDAY(DATE($D$4,7,1),2)+1+8)<>7,"",DATE($D$4,7,1)-WEEKDAY(DATE($D$4,7,1),2)+1+8) | D44: =IF(MONTH(DATE($D$4,7,1)-WEEKDAY(DATE($D$4,7,1),2)+1+9)<>7,"",DATE($D$4,7,1)-WEEKDAY(DATE($D$4,7,1),2)+1+9) | E44: =IF(MONTH(DATE($D$4,7,1)-WEEKDAY(DATE($D$4,7,1),2)+1+10)<>7,"",DATE($D$4,7,1)-WEEKDAY(DATE($D$4,7,1),2)+1+10) | F44: =IF(MONTH(DATE($D$4,7,1)-WEEKDAY(DATE($D$4,7,1),2)+1+11)<>7,"",DATE($D$4,7,1)-WEEKDAY(DATE($D$4,7,1),2)+1+11) | G44: =IF(MONTH(DATE($D$4,7,1)-WEEKDAY(DATE($D$4,7,1),2)+1+12)<>7,"",DATE($D$4,7,1)-WEEKDAY(DATE($D$4,7,1),2)+1+12) | H44: =IF(MONTH(DATE($D$4,7,1)-WEEKDAY(DATE($D$4,7,1),2)+1+13)<>7,"",DATE($D$4,7,1)-WEEKDAY(DATE($D$4,7,1),2)+1+13) | J44: =IF(MONTH(DATE($D$4,8,1)-WEEKDAY(DATE($D$4,8,1),2)+1+7)<>8,"",DATE($D$4,8,1)-WEEKDAY(DATE($D$4,8,1),2)+1+7) | K44: =IF(MONTH(DATE($D$4,8,1)-WEEKDAY(DATE($D$4,8,1),2)+1+8)<>8,"",DATE($D$4,8,1)-WEEKDAY(DATE($D$4,8,1),2)+1+8) | L44: =IF(MONTH(DATE($D$4,8,1)-WEEKDAY(DATE($D$4,8,1),2)+1+9)<>8,"",DATE($D$4,8,1)-WEEKDAY(DATE($D$4,8,1),2)+1+9) | M44: =IF(MONTH(DATE($D$4,8,1)-WEEKDAY(DATE($D$4,8,1),2)+1+10)<>8,"",DATE($D$4,8,1)-WEEKDAY(DATE($D$4,8,1),2)+1+10) | N44: =IF(MONTH(DATE($D$4,8,1)-WEEKDAY(DATE($D$4,8,1),2)+1+11)<>8,"",DATE($D$4,8,1)-WEEKDAY(DATE($D$4,8,1),2)+1+11) | O44: =IF(MONTH(DATE($D$4,8,1)-WEEKDAY(DATE($D$4,8,1),2)+1+12)<>8,"",DATE($D$4,8,1)-WEEKDAY(DATE($D$4,8,1),2)+1+12) | P44: =IF(MONTH(DATE($D$4,8,1)-WEEKDAY(DATE($D$4,8,1),2)+1+13)<>8,"",DATE($D$4,8,1)-WEEKDAY(DATE($D$4,8,1),2)+1+13) | R44: =IF(MONTH(DATE($D$4,9,1)-WEEKDAY(DATE($D$4,9,1),2)+1+7)<>9,"",DATE($D$4,9,1)-WEEKDAY(DATE($D$4,9,1),2)+1+7) | S44: =IF(MONTH(DATE($D$4,9,1)-WEEKDAY(DATE($D$4,9,1),2)+1+8)<>9,"",DATE($D$4,9,1)-WEEKDAY(DATE($D$4,9,1),2)+1+8) | T44: =IF(MONTH(DATE($D$4,9,1)-WEEKDAY(DATE($D$4,9,1),2)+1+9)<>9,"",DATE($D$4,9,1)-WEEKDAY(DATE($D$4,9,1),2)+1+9) | U44: =IF(MONTH(DATE($D$4,9,1)-WEEKDAY(DATE($D$4,9,1),2)+1+10)<>9,"",DATE($D$4,9,1)-WEEKDAY(DATE($D$4,9,1),2)+1+10) | V44: =IF(MONTH(DATE($D$4,9,1)-WEEKDAY(DATE($D$4,9,1),2)+1+11)<>9,"",DATE($D$4,9,1)-WEEKDAY(DATE($D$4,9,1),2)+1+11) | W44: =IF(MONTH(DATE($D$4,9,1)-WEEKDAY(DATE($D$4,9,1),2)+1+12)<>9,"",DATE($D$4,9,1)-WEEKDAY(DATE($D$4,9,1),2)+1+12) | X44: =IF(MONTH(DATE($D$4,9,1)-WEEKDAY(DATE($D$4,9,1),2)+1+13)<>9,"",DATE($D$4,9,1)-WEEKDAY(DATE($D$4,9,1),2)+1+13)
B45: =IF(MONTH(DATE($D$4,7,1)-WEEKDAY(DATE($D$4,7,1),2)+1+14)<>7,"",DATE($D$4,7,1)-WEEKDAY(DATE($D$4,7,1),2)+1+14) | C45: =IF(MONTH(DATE($D$4,7,1)-WEEKDAY(DATE($D$4,7,1),2)+1+15)<>7,"",DATE($D$4,7,1)-WEEKDAY(DATE($D$4,7,1),2)+1+15) | D45: =IF(MONTH(DATE($D$4,7,1)-WEEKDAY(DATE($D$4,7,1),2)+1+16)<>7,"",DATE($D$4,7,1)-WEEKDAY(DATE($D$4,7,1),2)+1+16) | E45: =IF(MONTH(DATE($D$4,7,1)-WEEKDAY(DATE($D$4,7,1),2)+1+17)<>7,"",DATE($D$4,7,1)-WEEKDAY(DATE($D$4,7,1),2)+1+17) | F45: =IF(MONTH(DATE($D$4,7,1)-WEEKDAY(DATE($D$4,7,1),2)+1+18)<>7,"",DATE($D$4,7,1)-WEEKDAY(DATE($D$4,7,1),2)+1+18) | G45: =IF(MONTH(DATE($D$4,7,1)-WEEKDAY(DATE($D$4,7,1),2)+1+19)<>7,"",DATE($D$4,7,1)-WEEKDAY(DATE($D$4,7,1),2)+1+19) | H45: =IF(MONTH(DATE($D$4,7,1)-WEEKDAY(DATE($D$4,7,1),2)+1+20)<>7,"",DATE($D$4,7,1)-WEEKDAY(DATE($D$4,7,1),2)+1+20) | J45: =IF(MONTH(DATE($D$4,8,1)-WEEKDAY(DATE($D$4,8,1),2)+1+14)<>8,"",DATE($D$4,8,1)-WEEKDAY(DATE($D$4,8,1),2)+1+14) | K45: =IF(MONTH(DATE($D$4,8,1)-WEEKDAY(DATE($D$4,8,1),2)+1+15)<>8,"",DATE($D$4,8,1)-WEEKDAY(DATE($D$4,8,1),2)+1+15) | L45: =IF(MONTH(DATE($D$4,8,1)-WEEKDAY(DATE($D$4,8,1),2)+1+16)<>8,"",DATE($D$4,8,1)-WEEKDAY(DATE($D$4,8,1),2)+1+16) | M45: =IF(MONTH(DATE($D$4,8,1)-WEEKDAY(DATE($D$4,8,1),2)+1+17)<>8,"",DATE($D$4,8,1)-WEEKDAY(DATE($D$4,8,1),2)+1+17) | N45: =IF(MONTH(DATE($D$4,8,1)-WEEKDAY(DATE($D$4,8,1),2)+1+18)<>8,"",DATE($D$4,8,1)-WEEKDAY(DATE($D$4,8,1),2)+1+18) | O45: =IF(MONTH(DATE($D$4,8,1)-WEEKDAY(DATE($D$4,8,1),2)+1+19)<>8,"",DATE($D$4,8,1)-WEEKDAY(DATE($D$4,8,1),2)+1+19) | P45: =IF(MONTH(DATE($D$4,8,1)-WEEKDAY(DATE($D$4,8,1),2)+1+20)<>8,"",DATE($D$4,8,1)-WEEKDAY(DATE($D$4,8,1),2)+1+20) | R45: =IF(MONTH(DATE($D$4,9,1)-WEEKDAY(DATE($D$4,9,1),2)+1+14)<>9,"",DATE($D$4,9,1)-WEEKDAY(DATE($D$4,9,1),2)+1+14) | S45: =IF(MONTH(DATE($D$4,9,1)-WEEKDAY(DATE($D$4,9,1),2)+1+15)<>9,"",DATE($D$4,9,1)-WEEKDAY(DATE($D$4,9,1),2)+1+15) | T45: =IF(MONTH(DATE($D$4,9,1)-WEEKDAY(DATE($D$4,9,1),2)+1+16)<>9,"",DATE($D$4,9,1)-WEEKDAY(DATE($D$4,9,1),2)+1+16) | U45: =IF(MONTH(DATE($D$4,9,1)-WEEKDAY(DATE($D$4,9,1),2)+1+17)<>9,"",DATE($D$4,9,1)-WEEKDAY(DATE($D$4,9,1),2)+1+17) | V45: =IF(MONTH(DATE($D$4,9,1)-WEEKDAY(DATE($D$4,9,1),2)+1+18)<>9,"",DATE($D$4,9,1)-WEEKDAY(DATE($D$4,9,1),2)+1+18) | W45: =IF(MONTH(DATE($D$4,9,1)-WEEKDAY(DATE($D$4,9,1),2)+1+19)<>9,"",DATE($D$4,9,1)-WEEKDAY(DATE($D$4,9,1),2)+1+19) | X45: =IF(MONTH(DATE($D$4,9,1)-WEEKDAY(DATE($D$4,9,1),2)+1+20)<>9,"",DATE($D$4,9,1)-WEEKDAY(DATE($D$4,9,1),2)+1+20)
B46: =IF(MONTH(DATE($D$4,7,1)-WEEKDAY(DATE($D$4,7,1),2)+1+21)<>7,"",DATE($D$4,7,1)-WEEKDAY(DATE($D$4,7,1),2)+1+21) | C46: =IF(MONTH(DATE($D$4,7,1)-WEEKDAY(DATE($D$4,7,1),2)+1+22)<>7,"",DATE($D$4,7,1)-WEEKDAY(DATE($D$4,7,1),2)+1+22) | D46: =IF(MONTH(DATE($D$4,7,1)-WEEKDAY(DATE($D$4,7,1),2)+1+23)<>7,"",DATE($D$4,7,1)-WEEKDAY(DATE($D$4,7,1),2)+1+23) | E46: =IF(MONTH(DATE($D$4,7,1)-WEEKDAY(DATE($D$4,7,1),2)+1+24)<>7,"",DATE($D$4,7,1)-WEEKDAY(DATE($D$4,7,1),2)+1+24) | F46: =IF(MONTH(DATE($D$4,7,1)-WEEKDAY(DATE($D$4,7,1),2)+1+25)<>7,"",DATE($D$4,7,1)-WEEKDAY(DATE($D$4,7,1),2)+1+25) | G46: =IF(MONTH(DATE($D$4,7,1)-WEEKDAY(DATE($D$4,7,1),2)+1+26)<>7,"",DATE($D$4,7,1)-WEEKDAY(DATE($D$4,7,1),2)+1+26) | H46: =IF(MONTH(DATE($D$4,7,1)-WEEKDAY(DATE($D$4,7,1),2)+1+27)<>7,"",DATE($D$4,7,1)-WEEKDAY(DATE($D$4,7,1),2)+1+27) | J46: =IF(MONTH(DATE($D$4,8,1)-WEEKDAY(DATE($D$4,8,1),2)+1+21)<>8,"",DATE($D$4,8,1)-WEEKDAY(DATE($D$4,8,1),2)+1+21) | K46: =IF(MONTH(DATE($D$4,8,1)-WEEKDAY(DATE($D$4,8,1),2)+1+22)<>8,"",DATE($D$4,8,1)-WEEKDAY(DATE($D$4,8,1),2)+1+22) | L46: =IF(MONTH(DATE($D$4,8,1)-WEEKDAY(DATE($D$4,8,1),2)+1+23)<>8,"",DATE($D$4,8,1)-WEEKDAY(DATE($D$4,8,1),2)+1+23) | M46: =IF(MONTH(DATE($D$4,8,1)-WEEKDAY(DATE($D$4,8,1),2)+1+24)<>8,"",DATE($D$4,8,1)-WEEKDAY(DATE($D$4,8,1),2)+1+24) | N46: =IF(MONTH(DATE($D$4,8,1)-WEEKDAY(DATE($D$4,8,1),2)+1+25)<>8,"",DATE($D$4,8,1)-WEEKDAY(DATE($D$4,8,1),2)+1+25) | O46: =IF(MONTH(DATE($D$4,8,1)-WEEKDAY(DATE($D$4,8,1),2)+1+26)<>8,"",DATE($D$4,8,1)-WEEKDAY(DATE($D$4,8,1),2)+1+26) | P46: =IF(MONTH(DATE($D$4,8,1)-WEEKDAY(DATE($D$4,8,1),2)+1+27)<>8,"",DATE($D$4,8,1)-WEEKDAY(DATE($D$4,8,1),2)+1+27) | R46: =IF(MONTH(DATE($D$4,9,1)-WEEKDAY(DATE($D$4,9,1),2)+1+21)<>9,"",DATE($D$4,9,1)-WEEKDAY(DATE($D$4,9,1),2)+1+21) | S46: =IF(MONTH(DATE($D$4,9,1)-WEEKDAY(DATE($D$4,9,1),2)+1+22)<>9,"",DATE($D$4,9,1)-WEEKDAY(DATE($D$4,9,1),2)+1+22) | T46: =IF(MONTH(DATE($D$4,9,1)-WEEKDAY(DATE($D$4,9,1),2)+1+23)<>9,"",DATE($D$4,9,1)-WEEKDAY(DATE($D$4,9,1),2)+1+23) | U46: =IF(MONTH(DATE($D$4,9,1)-WEEKDAY(DATE($D$4,9,1),2)+1+24)<>9,"",DATE($D$4,9,1)-WEEKDAY(DATE($D$4,9,1),2)+1+24) | V46: =IF(MONTH(DATE($D$4,9,1)-WEEKDAY(DATE($D$4,9,1),2)+1+25)<>9,"",DATE($D$4,9,1)-WEEKDAY(DATE($D$4,9,1),2)+1+25) | W46: =IF(MONTH(DATE($D$4,9,1)-WEEKDAY(DATE($D$4,9,1),2)+1+26)<>9,"",DATE($D$4,9,1)-WEEKDAY(DATE($D$4,9,1),2)+1+26) | X46: =IF(MONTH(DATE($D$4,9,1)-WEEKDAY(DATE($D$4,9,1),2)+1+27)<>9,"",DATE($D$4,9,1)-WEEKDAY(DATE($D$4,9,1),2)+1+27)
B47: =IF(MONTH(DATE($D$4,7,1)-WEEKDAY(DATE($D$4,7,1),2)+1+28)<>7,"",DATE($D$4,7,1)-WEEKDAY(DATE($D$4,7,1),2)+1+28) | C47: =IF(MONTH(DATE($D$4,7,1)-WEEKDAY(DATE($D$4,7,1),2)+1+29)<>7,"",DATE($D$4,7,1)-WEEKDAY(DATE($D$4,7,1),2)+1+29) | D47: =IF(MONTH(DATE($D$4,7,1)-WEEKDAY(DATE($D$4,7,1),2)+1+30)<>7,"",DATE($D$4,7,1)-WEEKDAY(DATE($D$4,7,1),2)+1+30) | E47: =IF(MONTH(DATE($D$4,7,1)-WEEKDAY(DATE($D$4,7,1),2)+1+31)<>7,"",DATE($D$4,7,1)-WEEKDAY(DATE($D$4,7,1),2)+1+31) | F47: =IF(MONTH(DATE($D$4,7,1)-WEEKDAY(DATE($D$4,7,1),2)+1+32)<>7,"",DATE($D$4,7,1)-WEEKDAY(DATE($D$4,7,1),2)+1+32) | G47: =IF(MONTH(DATE($D$4,7,1)-WEEKDAY(DATE($D$4,7,1),2)+1+33)<>7,"",DATE($D$4,7,1)-WEEKDAY(DATE($D$4,7,1),2)+1+33) | H47: =IF(MONTH(DATE($D$4,7,1)-WEEKDAY(DATE($D$4,7,1),2)+1+34)<>7,"",DATE($D$4,7,1)-WEEKDAY(DATE($D$4,7,1),2)+1+34) | J47: =IF(MONTH(DATE($D$4,8,1)-WEEKDAY(DATE($D$4,8,1),2)+1+28)<>8,"",DATE($D$4,8,1)-WEEKDAY(DATE($D$4,8,1),2)+1+28) | K47: =IF(MONTH(DATE($D$4,8,1)-WEEKDAY(DATE($D$4,8,1),2)+1+29)<>8,"",DATE($D$4,8,1)-WEEKDAY(DATE($D$4,8,1),2)+1+29) | L47: =IF(MONTH(DATE($D$4,8,1)-WEEKDAY(DATE($D$4,8,1),2)+1+30)<>8,"",DATE($D$4,8,1)-WEEKDAY(DATE($D$4,8,1),2)+1+30) | M47: =IF(MONTH(DATE($D$4,8,1)-WEEKDAY(DATE($D$4,8,1),2)+1+31)<>8,"",DATE($D$4,8,1)-WEEKDAY(DATE($D$4,8,1),2)+1+31) | N47: =IF(MONTH(DATE($D$4,8,1)-WEEKDAY(DATE($D$4,8,1),2)+1+32)<>8,"",DATE($D$4,8,1)-WEEKDAY(DATE($D$4,8,1),2)+1+32) | O47: =IF(MONTH(DATE($D$4,8,1)-WEEKDAY(DATE($D$4,8,1),2)+1+33)<>8,"",DATE($D$4,8,1)-WEEKDAY(DATE($D$4,8,1),2)+1+33) | P47: =IF(MONTH(DATE($D$4,8,1)-WEEKDAY(DATE($D$4,8,1),2)+1+34)<>8,"",DATE($D$4,8,1)-WEEKDAY(DATE($D$4,8,1),2)+1+34) | R47: =IF(MONTH(DATE($D$4,9,1)-WEEKDAY(DATE($D$4,9,1),2)+1+28)<>9,"",DATE($D$4,9,1)-WEEKDAY(DATE($D$4,9,1),2)+1+28) | S47: =IF(MONTH(DATE($D$4,9,1)-WEEKDAY(DATE($D$4,9,1),2)+1+29)<>9,"",DATE($D$4,9,1)-WEEKDAY(DATE($D$4,9,1),2)+1+29) | T47: =IF(MONTH(DATE($D$4,9,1)-WEEKDAY(DATE($D$4,9,1),2)+1+30)<>9,"",DATE($D$4,9,1)-WEEKDAY(DATE($D$4,9,1),2)+1+30) | U47: =IF(MONTH(DATE($D$4,9,1)-WEEKDAY(DATE($D$4,9,1),2)+1+31)<>9,"",DATE($D$4,9,1)-WEEKDAY(DATE($D$4,9,1),2)+1+31) | V47: =IF(MONTH(DATE($D$4,9,1)-WEEKDAY(DATE($D$4,9,1),2)+1+32)<>9,"",DATE($D$4,9,1)-WEEKDAY(DATE($D$4,9,1),2)+1+32) | W47: =IF(MONTH(DATE($D$4,9,1)-WEEKDAY(DATE($D$4,9,1),2)+1+33)<>9,"",DATE($D$4,9,1)-WEEKDAY(DATE($D$4,9,1),2)+1+33) | X47: =IF(MONTH(DATE($D$4,9,1)-WEEKDAY(DATE($D$4,9,1),2)+1+34)<>9,"",DATE($D$4,9,1)-WEEKDAY(DATE($D$4,9,1),2)+1+34)
...

Sheet Balance
B1: BALANCE GENERAL
B2: Foto de hoy: lo que tienes menos lo que debes. Los saldos y las líneas de crédito se reparten entre tu economía y la del hogar según la columna Ámbito de la hoja Disponibilidad; las facturas heredan el ámbito de la cuenta desde la que se pagan.
B4: Balance a fin del periodo seleccionado | C4: =EOMONTH(Panel!$H$5,0) | D4: =Panel!$I$4 | E4: Los pasivos por facturas se filtran a esa fecha. Los saldos bancarios usan el histórico de cierres si lo has rellenado; si no, los de hoy.
B6: Concepto | C6: Tú (€) | D6: Hogar (€) | E6: CONSOLIDADO (€) | F6: % s/activo | G6: Notas | I6: Datos para los gráficos
B7: ACTIVO | I7: Concepto | J7: €
B8: Activo corriente (lo que es dinero o se convierte en dinero en menos de un año) | I8: Activo corriente | J8: =$E$13
